Workbook
Name 是否经营农险: [12]封面!$B$25
Name 类型: OFFSET([18]字段!$L$11,,,COUNTA([18]字段!$L$1:$L$65536),)
Name 开户行: OFFSET([18]字段!$M$11,,,COUNTA([18]字段!$M$1:$M$65536),)
Name 关于: #REF!
Name 古2: #REF!
Name 公司类型: [12]封面!$B$4
Name 公司类别: [12]封面!#REF!
Name 部门: OFFSET([18]字段!$C$11,,,COUNTA([18]字段!$C$1:$C$65536),)
Name Year_1MC: [3]偿付能力计算!#REF!
Name Total_Pay: #REF!
Name Total_asset_PV: #REF!
Name TorF: [5]目录!$B$123:$B$164,[5]目录!$D$123:$D$164
Name TAX: [1]Inputs!$D$220
Name SURR_NP_TBL: [1]CSV!$V$1:$W$5
Name SURR_MORT_LOAD_TBL: [1]Mortality_Assump!$A$46:$IV$47
Name SURR_MORT: [1]Inputs!$D$193
Name Total_Payment: Scheduled_Payment+Extra_Payment
Name SURR_INT_MTH: [1]Inputs!$E$197
Name SURR_CIRCSA_LOAD_TBL: [1]RES_SURR_BASIS!#REF!
Name SURR_CIRCAP_TBL: [1]Inputs!$C$202:$E$206
Name SURR_CIRCAP_LOAD_TBL: [1]RES_SURR_BASIS!$A$37:$IV$41
Name SURR_CIRC_TBL: [1]Inputs!$C$202:$D$206
Name SURR_CIRC_LOAD_TBL: [1]RES_SURR_BASIS!$A$31:$IV$35
Name ST_DATE: [1]Results!#REF!
Name SOLVE: #REF!
Name SM_TBL: #REF!
Name SM_RES: [1]Inputs!$D$228
Name SURR_NP_MTD: [1]Inputs!$D$195
Name SM_COL: #REF!
Name 责任人: OFFSET([18]字段!$F$11,,,COUNTA([18]字段!$F$1:$F$65536),)
Name SCN_NO: [1]Inputs!$D$62
Name Scheduled_Monthly_Payment: #REF!
Name Scheduled_Interest_Rate: #REF!
Name SALES_SORT: '[2]Dashboard data'!$B$70:$D$99
Name SALES_FCST_ROWS: '[2]Sales Fcst'!$A$20:$IV$34,'[2]Sales Fcst'!$A$54:$IV$68,'[2]Sales Fcst'!$A$87:$IV$101
Name SA: [1]Inputs!$D$18
Name RES_TERM: [1]Inputs!$D$168
Name RES_SURR_TBL: [1]RES_SURR_BASIS!$A$2:$IV$65536
Name RES_MORT_LOAD_TBL: [1]Mortality_Assump!$A$40:$IV$41
Name RES_MORT_LOAD_DPER: [1]Inputs!$D$188
Name RES_MTD_ADJ: [1]Inputs!$D$166
Name RES_INT_MTH: [1]Inputs!$E$167
Name RES_CIRC_LOAD_TBL: [1]RES_SURR_BASIS!$A$14:$IV$18
Name Reg_Curve_Low: [3]曲线输入!$AH$2
Name RE_PREM: [1]Inputs!$E$69
Name RDR_ANN: [1]Inputs!$D$221
Name 支票号: OFFSET([18]支票领购与使用输入!$J$11,,,COUNTA([18]支票领购与使用输入!$J$1:$J$65536),)
Name PY_SALES: '[2]P&L (PY Act)'!$B$5:$T$35
Name PREM_SA: #REF!
Name unit: #REF!
Name PREM_RDR_MTH: #REF!
Name PREM_RDR_DMTH: #REF!
Name PREM_RDR: #REF!
Name PREM_PTERM: #REF!
Name PREM_PREM_F: #REF!
Name PREM_POL_TERM: #REF!
Name PREM_TERM: [1]Inputs!$D$21
Name PREM_MULT_TIME: #REF!
Name PREM_MULT_NAME: #REF!
Name PREM_MULT_INDEX: #REF!

Sheet 资产明细
A2: 45657 | B2: 资产唯一识别码/AssetUniqueIdentification | C2: 资产名称/AssetName | D2: 保险账户分类/InsuranceAccountType | E2: 资产配置分类一级/SAAAssetTypeLevel1 | F2: 资产配置分类二级/SAAAssetTypeLevel2 | G2: 资产配置分类三级/SAAAssetTypeLevel3 | H2: ALM五级分类/ALMClassificationLevel5 | I2: 偿付能力分类/SolvencyType | J2: 会计分类/AccountingType | K2: 资产组合名称/PortfolioName | L2: 建模类型/ModelType | M2: 净价市场价值/CleanMarketValue | N2: 风险暴露/EX | O2: 应收利息风险暴露/InterestEX | P2: 购买价格/PurchasePrice | Q2: 摊余成本/AmortizedCost | R2: 净价账面价值/CleanAccountingValue | S2: 应收利息/AccruedInterest | T2: 付息频率/Frequency | U2: 购买日/StartDate | V2: 首次付息日/FirstCouponDate | W2: 到期日/EndDate | X2: 特殊条款/SpecialTerms | Y2: 预期投资收益率/ExpectedReturn | Z2: 基准曲线/BenchmarkCurve | AA2: 信用利差风险因子/CreditSpreadRiskFactor | AB2: 非流动性溢价风险因子/IlliquidityPremiumRiskFactor | AC2: 权益风险因子/EquityRiskFactor | AD2: 面值/Notional | AE2: 面值2/Notional2 | AF2: 面值3/Notional3 | AG2: 面值4/Notional4 | AH2: 面值5/Notional5 | AI2: 提前还本日2/Date2 | AJ2: 提前还本日3/Date3 | AK2: 提前还本日4/Date4 | AL2: 提前还本日5/Date5 | AM2: 票息率/CouponRate | AN2: 票息率2/CouponRate2 | AO2: 票息率3/CouponRate3 | AP2: 票息率4/CouponRate4 | AQ2: 票息率5/CouponRate5 | AR2: 票息日期2/CouponRateDate2 | AS2: 票息日期3/CouponRateDate3 | AT2: 票息日期4/CouponRateDate4 | AU2: 票息日期5/CouponRateDate5 | AV2: 行权判断1/OptionExcercise1 | AW2: 行权判断2/OptionExcercise2 | AX2: 行权判断3/OptionExcercise3 | AY2: 行权判断4/OptionExcercise4 | AZ2: 行权判断5/OptionExcercise5 | BA2: 行权日期1/OptionExcerciseDate1 | BB2: 行权日期2/OptionExcerciseDate2 | BC2: 行权日期3/OptionExcerciseDate3 | BD2: 行权日期4/OptionExcerciseDate4 | BE2: 行权日期5/OptionExcerciseDate5 | BF2: 实际利率/CostYTM | BG2: 分红率/DividendYield | BH2: AFS资产历史累计浮盈浮亏/AFSAccumulatedUnrealisedGain | BI2: AFS资产当期浮盈浮亏变现比/AFSCurrentGainRealizationRatio | BJ2: 违约风险1/PDMarginal1 | BK2: 违约损失率1/LossGivenDefault1 | BL2: 违约风险2/PDMarginal2 | BM2: 违约损失率2/LossGivenDefault2 | BN2: 预计信用变化/ExpectedCreditState
A3: 3 | B3: 国债_3Y | C3: 国债_3Y | D3: 传统账户 | E3: 固定收益类 | F3: 国债 | G3: 国债_3Y | I3: Generic_国债_3Y | J3: AFS | K3: 国债_3Y | L3: 标准固收类 | M3: ==IF($D3=配置调整!$A$5,VLOOKUP($K3,配置调整!$B$4:$O$29,6,0)*配置调整!$A$6,IF($D3=配置调整!$A$8,VLOOKUP($K3,配置调整!$B$4:$O$29,6,0)*配置调整!$A$9,IF($D3=配置调整!$A$11,VLOOKUP($K3,配置调整!$B$4:$O$29,6,0)*配置调整!$A$12,FALSE))) -> 98950474 | N3: ==M3 -> 98950474 | O3: 0 | P3: ==M3 -> 98950474 | Q3: ==M3 -> 98950474 | R3: ==M3 -> 98950474 | S3: 0 | T3: 1 | U3: ==IF(OR(L3="标准固收类",L3="非标固收类"),$A$2,"") -> 45657 | V3: ==IF(OR(L3="标准固收类",L3="非标固收类"),EOMONTH($A$2,12),"") -> 46022 | W3: ==IF(OR(L3="标准固收类",L3="非标固收类"),EOMONTH($A$2,A3*12),"") -> 46752 | X3: 不适用 | Y3: ==VLOOKUP(资产明细!K3,配置调整!$B$4:$C$29,2,0) -> 0.011872 | Z3: Govt | AD3: ==P3 -> 98950474 | AM3: ==IF(OR(L3="标准固收类",L3="非标固收类"),Y3,"") -> 0.011872 | BF3: ==AM3 -> 0.011872 | BG3: ==IF(OR(L3="标准固收类",L3="非标固收类"),"",MIN(Y3,2%)) | BH3: 0 | BI3: 0.85
A4: 5 | B4: 国债_5Y | C4: 国债_5Y | D4: 传统账户 | E4: 固定收益类 | F4: 国债 | G4: 国债_5Y | I4: Generic_国债_5Y | J4: AFS | K4: 国债_5Y | L4: 标准固收类 | M4: ==IF($D4=配置调整!$A$5,VLOOKUP($K4,配置调整!$B$4:$O$29,6,0)*配置调整!$A$6,IF($D4=配置调整!$A$8,VLOOKUP($K4,配置调整!$B$4:$O$29,6,0)*配置调整!$A$9,IF($D4=配置调整!$A$11,VLOOKUP($K4,配置调整!$B$4:$O$29,6,0)*配置调整!$A$12,FALSE))) -> 2.0840971e+08 | N4: ==M4 -> 2.0840971e+08 | O4: 0 | P4: ==M4 -> 2.0840971e+08 | Q4: ==M4 -> 2.0840971e+08 | R4: ==M4 -> 2.0840971e+08 | S4: 0 | T4: 1 | U4: ==IF(OR(L4="标准固收类",L4="非标固收类"),$A$2,"") -> 45657 | V4: ==IF(OR(L4="标准固收类",L4="非标固收类"),EOMONTH($A$2,12),"") -> 46022 | W4: ==IF(OR(L4="标准固收类",L4="非标固收类"),EOMONTH($A$2,A4*12),"") -> 47483 | X4: 不适用 | Y4: ==VLOOKUP(资产明细!K4,配置调整!$B$4:$C$29,2,0) -> 0.014152 | Z4: Govt | AD4: ==P4 -> 2.0840971e+08 | AM4: ==IF(OR(L4="标准固收类",L4="非标固收类"),Y4,"") -> 0.014152 | BF4: ==AM4 -> 0.014152 | BG4: ==IF(OR(L4="标准固收类",L4="非标固收类"),"",MIN(Y4,2%)) | BH4: 0 | BI4: 0.85
A5: 10 | B5: 国债_10Y | C5: 国债_10Y | D5: 传统账户 | E5: 固定收益类 | F5: 国债 | G5: 国债_10Y | I5: Generic_国债_10Y | J5: AFS | K5: 国债_10Y | L5: 标准固收类 | M5: ==IF($D5=配置调整!$A$5,VLOOKUP($K5,配置调整!$B$4:$O$29,6,0)*配置调整!$A$6,IF($D5=配置调整!$A$8,VLOOKUP($K5,配置调整!$B$4:$O$29,6,0)*配置调整!$A$9,IF($D5=配置调整!$A$11,VLOOKUP($K5,配置调整!$B$4:$O$29,6,0)*配置调整!$A$12,FALSE))) -> 8.6934539e+08 | N5: ==M5 -> 8.6934539e+08 | O5: 0 | P5: ==M5 -> 8.6934539e+08 | Q5: ==M5 -> 8.6934539e+08 | R5: ==M5 -> 8.6934539e+08 | S5: 0 | T5: 1 | U5: ==IF(OR(L5="标准固收类",L5="非标固收类"),$A$2,"") -> 45657 | V5: ==IF(OR(L5="标准固收类",L5="非标固收类"),EOMONTH($A$2,12),"") -> 46022 | W5: ==IF(OR(L5="标准固收类",L5="非标固收类"),EOMONTH($A$2,A5*12),"") -> 49309 | X5: 不适用 | Y5: ==VLOOKUP(资产明细!K5,配置调整!$B$4:$C$29,2,0) -> 0.016752 | Z5: Govt | AD5: ==P5 -> 8.6934539e+08 | AM5: ==IF(OR(L5="标准固收类",L5="非标固收类"),Y5,"") -> 0.016752 | BF5: ==AM5 -> 0.016752 | BG5: ==IF(OR(L5="标准固收类",L5="非标固收类"),"",MIN(Y5,2%)) | BH5: 0 | BI5: 0.85
A6: 20 | B6: 国债_20Y | C6: 国债_20Y | D6: 传统账户 | E6: 固定收益类 | F6: 国债 | G6: 国债_20Y | I6: Generic_国债_20Y | J6: AFS | K6: 国债_20Y | L6: 标准固收类 | M6: ==IF($D6=配置调整!$A$5,VLOOKUP($K6,配置调整!$B$4:$O$29,6,0)*配置调整!$A$6,IF($D6=配置调整!$A$8,VLOOKUP($K6,配置调整!$B$4:$O$29,6,0)*配置调整!$A$9,IF($D6=配置调整!$A$11,VLOOKUP($K6,配置调整!$B$4:$O$29,6,0)*配置调整!$A$12,FALSE))) -> 3.8019957e+09 | N6: ==M6 -> 3.8019957e+09 | O6: 0 | P6: ==M6 -> 3.8019957e+09 | Q6: ==M6 -> 3.8019957e+09 | R6: ==M6 -> 3.8019957e+09 | S6: 0 | T6: 1 | U6: ==IF(OR(L6="标准固收类",L6="非标固收类"),$A$2,"") -> 45657 | V6: ==IF(OR(L6="标准固收类",L6="非标固收类"),EOMONTH($A$2,12),"") -> 46022 | W6: ==IF(OR(L6="标准固收类",L6="非标固收类"),EOMONTH($A$2,A6*12),"") -> 52962 | X6: 不适用 | Y6: ==VLOOKUP(资产明细!K6,配置调整!$B$4:$C$29,2,0) -> 0.019747 | Z6: Govt | AD6: ==P6 -> 3.8019957e+09 | AM6: ==IF(OR(L6="标准固收类",L6="非标固收类"),Y6,"") -> 0.019747 | BF6: ==AM6 -> 0.019747 | BG6: ==IF(OR(L6="标准固收类",L6="非标固收类"),"",MIN(Y6,2%)) | BH6: 0 | BI6: 0.85
A7: 50 | B7: 国债_50Y | C7: 国债_50Y | D7: 传统账户 | E7: 固定收益类 | F7: 国债 | G7: 国债_50Y | I7: Generic_国债_50Y | J7: AFS | K7: 国债_50Y | L7: 标准固收类 | M7: ==IF($D7=配置调整!$A$5,VLOOKUP($K7,配置调整!$B$4:$O$29,6,0)*配置调整!$A$6,IF($D7=配置调整!$A$8,VLOOKUP($K7,配置调整!$B$4:$O$29,6,0)*配置调整!$A$9,IF($D7=配置调整!$A$11,VLOOKUP($K7,配置调整!$B$4:$O$29,6,0)*配置调整!$A$12,FALSE))) -> 5.5148303e+09 | N7: ==M7 -> 5.5148303e+09 | O7: 0 | P7: ==M7 -> 5.5148303e+09 | Q7: ==M7 -> 5.5148303e+09 | R7: ==M7 -> 5.5148303e+09 | S7: 0 | T7: 1 | U7: ==IF(OR(L7="标准固收类",L7="非标固收类"),$A$2,"") -> 45657 | V7: ==IF(OR(L7="标准固收类",L7="非标固收类"),EOMONTH($A$2,12),"") -> 46022 | W7: ==IF(OR(L7="标准固收类",L7="非标固收类"),EOMONTH($A$2,A7*12),"") -> 63919 | X7: 不适用 | Y7: ==VLOOKUP(资产明细!K7,配置调整!$B$4:$C$29,2,0) -> 0.019875 | Z7: Govt | AD7: ==P7 -> 5.5148303e+09 | AM7: ==IF(OR(L7="标准固收类",L7="非标固收类"),Y7,"") -> 0.019875 | BF7: ==AM7 -> 0.019875 | BG7: ==IF(OR(L7="标准固收类",L7="非标固收类"),"",MIN(Y7,2%)) | BH7: 0 | BI7: 0.85
A8: 3 | B8: 高等级信用债_3Y | C8: 高等级信用债_3Y | D8: 传统账户 | E8: 固定收益类 | F8: 高等级信用债 | G8: 高等级信用债_3Y | I8: Generic_高等级信用债_3Y | J8: AFS | K8: 信用债_3Y | L8: 标准固收类 | M8: ==IF($D8=配置调整!$A$5,VLOOKUP($K8,配置调整!$B$4:$O$29,6,0)*配置调整!$A$6,IF($D8=配置调整!$A$8,VLOOKUP($K8,配置调整!$B$4:$O$29,6,0)*配置调整!$A$9,IF($D8=配置调整!$A$11,VLOOKUP($K8,配置调整!$B$4:$O$29,6,0)*配置调整!$A$12,FALSE))) -> 1.8185257e+09 | N8: ==M8 -> 1.8185257e+09 | O8: 0 | P8: ==M8 -> 1.8185257e+09 | Q8: ==M8 -> 1.8185257e+09 | R8: ==M8 -> 1.8185257e+09 | S8: 0 | T8: 1 | U8: ==IF(OR(L8="标准固收类",L8="非标固收类"),$A$2,"") -> 45657 | V8: ==IF(OR(L8="标准固收类",L8="非标固收类"),EOMONTH($A$2,12),"") -> 46022 | W8: ==IF(OR(L8="标准固收类",L8="非标固收类"),EOMONTH($A$2,A8*12),"") -> 46752 | X8: 不适用 | Y8: ==VLOOKUP(资产明细!K8,配置调整!$B$4:$C$29,2,0) -> 0.017501 | Z8: Govt | AA8: CORIG0-3 | AD8: ==P8 -> 1.8185257e+09 | AM8: ==IF(OR(L8="标准固收类",L8="非标固收类"),Y8,"") -> 0.017501 | BF8: ==AM8 -> 0.017501 | BG8: ==IF(OR(L8="标准固收类",L8="非标固收类"),"",MIN(Y8,2%)) | BH8: 0 | BI8: 0.85
A9: 5 | B9: 高等级信用债_5Y | C9: 高等级信用债_5Y | D9: 传统账户 | E9: 固定收益类 | F9: 高等级信用债 | G9: 高等级信用债_5Y | I9: Generic_高等级信用债_5Y | J9: AFS | K9: 信用债_5Y | L9: 标准固收类 | M9: ==IF($D9=配置调整!$A$5,VLOOKUP($K9,配置调整!$B$4:$O$29,6,0)*配置调整!$A$6,IF($D9=配置调整!$A$8,VLOOKUP($K9,配置调整!$B$4:$O$29,6,0)*配置调整!$A$9,IF($D9=配置调整!$A$11,VLOOKUP($K9,配置调整!$B$4:$O$29,6,0)*配置调整!$A$12,FALSE))) -> 1.5992956e+08 | N9: ==M9 -> 1.5992956e+08 | O9: 0 | P9: ==M9 -> 1.5992956e+08 | Q9: ==M9 -> 1.5992956e+08 | R9: ==M9 -> 1.5992956e+08 | S9: 0 | T9: 1 | U9: ==IF(OR(L9="标准固收类",L9="非标固收类"),$A$2,"") -> 45657 | V9: ==IF(OR(L9="标准固收类",L9="非标固收类"),EOMONTH($A$2,12),"") -> 46022 | W9: ==IF(OR(L9="标准固收类",L9="非标固收类"),EOMONTH($A$2,A9*12),"") -> 47483 | X9: 不适用 | Y9: ==VLOOKUP(资产明细!K9,配置调整!$B$4:$C$29,2,0) -> 0.018727 | Z9: Govt | AA9: CORIG3+ | AD9: ==P9 -> 1.5992956e+08 | AM9: ==IF(OR(L9="标准固收类",L9="非标固收类"),Y9,"") -> 0.018727 | BF9: ==AM9 -> 0.018727 | BG9: ==IF(OR(L9="标准固收类",L9="非标固收类"),"",MIN(Y9,2%)) | BH9: 0 | BI9: 0.85
A10: 10 | B10: 高等级信用债_10Y | C10: 高等级信用债_10Y | D10: 传统账户 | E10: 固定收益类 | F10: 高等级信用债 | G10: 高等级信用债_10Y | I10: Generic_高等级信用债_10Y | J10: AFS | K10: 信用债_10Y | L10: 标准固收类 | M10: ==IF($D10=配置调整!$A$5,VLOOKUP($K10,配置调整!$B$4:$O$29,6,0)*配置调整!$A$6,IF($D10=配置调整!$A$8,VLOOKUP($K10,配置调整!$B$4:$O$29,6,0)*配置调整!$A$9,IF($D10=配置调整!$A$11,VLOOKUP($K10,配置调整!$B$4:$O$29,6,0)*配置调整!$A$12,FALSE))) -> 1.0469498e+09 | N10: ==M10 -> 1.0469498e+09 | O10: 0 | P10: ==M10 -> 1.0469498e+09 | Q10: ==M10 -> 1.0469498e+09 | R10: ==M10 -> 1.0469498e+09 | S10: 0 | T10: 1 | U10: ==IF(OR(L10="标准固收类",L10="非标固收类"),$A$2,"") -> 45657 | V10: ==IF(OR(L10="标准固收类",L10="非标固收类"),EOMONTH($A$2,12),"") -> 46022 | W10: ==IF(OR(L10="标准固收类",L10="非标固收类"),EOMONTH($A$2,A10*12),"") -> 49309 | X10: 不适用 | Y10: ==VLOOKUP(资产明细!K10,配置调整!$B$4:$C$29,2,0) -> 0.021173 | Z10: Govt | AA10: CORIG3+ | AD10: ==P10 -> 1.0469498e+09 | AM10: ==IF(OR(L10="标准固收类",L10="非标固收类"),Y10,"") -> 0.021173 | BF10: ==AM10 -> 0.021173 | BG10: ==IF(OR(L10="标准固收类",L10="非标固收类"),"",MIN(Y10,2%)) | BH10: 0 | BI10: 0.85
A11: 3 | B11: 非标资产_3Y | C11: 非标资产_3Y | D11: 传统账户 | E11: 固定收益类 | F11: 非标资产 | G11: 非标资产_3Y | I11: Generic_非标资产_3Y | J11: AFS | K11: 非标资产_3Y | L11: 非标固收类 | M11: ==IF($D11=配置调整!$A$5,VLOOKUP($K11,配置调整!$B$4:$O$29,6,0)*配置调整!$A$6,IF($D11=配置调整!$A$8,VLOOKUP($K11,配置调整!$B$4:$O$29,6,0)*配置调整!$A$9,IF($D11=配置调整!$A$11,VLOOKUP($K11,配置调整!$B$4:$O$29,6,0)*配置调整!$A$12,FALSE))) -> 7.6756732e+08 | N11: ==M11 -> 7.6756732e+08 | O11: 0 | P11: ==M11 -> 7.6756732e+08 | Q11: ==M11 -> 7.6756732e+08 | R11: ==M11 -> 7.6756732e+08 | S11: 0 | T11: 1 | U11: ==IF(OR(L11="标准固收类",L11="非标固收类"),$A$2,"") -> 45657 | V11: ==IF(OR(L11="标准固收类",L11="非标固收类"),EOMONTH($A$2,12),"") -> 46022 | W11: ==IF(OR(L11="标准固收类",L11="非标固收类"),EOMONTH($A$2,A11*12),"") -> 46752 | X11: 不适用 | Y11: ==VLOOKUP(资产明细!K11,配置调整!$B$4:$C$29,2,0) -> 0.024290322 | Z11: Govt | AA11: CORIG3+ | AB11: IP 3Y | AD11: ==P11 -> 7.6756732e+08 | AM11: ==IF(OR(L11="标准固收类",L11="非标固收类"),Y11,"") -> 0.024290322 | BF11: ==AM11 -> 0.024290322 | BG11: ==IF(OR(L11="标准固收类",L11="非标固收类"),"",MIN(Y11,2%)) | BH11: 0 | BI11: 0.85
A12: 5 | B12: 非标资产_5Y | C12: 非标资产_5Y | D12: 传统账户 | E12: 固定收益类 | F12: 非标资产 | G12: 非标资产_5Y | I12: Generic_非标资产_5Y | J12: AFS | K12: 非标资产_5Y | L12: 非标固收类 | M12: ==IF($D12=配置调整!$A$5,VLOOKUP($K12,配置调整!$B$4:$O$29,6,0)*配置调整!$A$6,IF($D12=配置调整!$A$8,VLOOKUP($K12,配置调整!$B$4:$O$29,6,0)*配置调整!$A$9,IF($D12=配置调整!$A$11,VLOOKUP($K12,配置调整!$B$4:$O$29,6,0)*配置调整!$A$12,FALSE))) -> 5.0298086e+08 | N12: ==M12 -> 5.0298086e+08 | O12: 0 | P12: ==M12 -> 5.0298086e+08 | Q12: ==M12 -> 5.0298086e+08 | R12: ==M12 -> 5.0298086e+08 | S12: 0 | T12: 1 | U12: ==IF(OR(L12="标准固收类",L12="非标固收类"),$A$2,"") -> 45657 | V12: ==IF(OR(L12="标准固收类",L12="非标固收类"),EOMONTH($A$2,12),"") -> 46022 | W12: ==IF(OR(L12="标准固收类",L12="非标固收类"),EOMONTH($A$2,A12*12),"") -> 47483 | X12: 不适用 | Y12: ==VLOOKUP(资产明细!K12,配置调整!$B$4:$C$29,2,0) -> 0.025629035 | Z12: Govt | AA12: CORIG3+ | AB12: IP 5Y | AD12: ==P12 -> 5.0298086e+08 | AM12: ==IF(OR(L12="标准固收类",L12="非标固收类"),Y12,"") -> 0.025629035 | BF12: ==AM12 -> 0.025629035 | BG12: ==IF(OR(L12="标准固收类",L12="非标固收类"),"",MIN(Y12,2%)) | BH12: 0 | BI12: 0.85
B13: A股 | C13: A股 | D13: 传统账户 | E13: 权益类 | F13: 上市普通股票 | G13: A股 | I13: Generic_A股 | J13: AFS | K13: A股 | L13: 权益类 | M13: ==IF($D13=配置调整!$A$5,VLOOKUP($K13,配置调整!$B$4:$O$29,6,0)*配置调整!$A$6,IF($D13=配置调整!$A$8,VLOOKUP($K13,配置调整!$B$4:$O$29,6,0)*配置调整!$A$9,IF($D13=配置调整!$A$11,VLOOKUP($K13,配置调整!$B$4:$O$29,6,0)*配置调整!$A$12,FALSE))) -> 267518.43 | N13: ==M13 -> 267518.43 | O13: 0 | P13: ==M13 -> 267518.43 | Q13: ==M13 -> 267518.43 | R13: ==M13 -> 267518.43 | S13: 0 | U13: ==IF(OR(L13="标准固收类",L13="非标固收类"),$A$2,"") | V13: ==IF(OR(L13="标准固收类",L13="非标固收类"),EOMONTH($A$2,12),"") | W13: ==IF(OR(L13="标准固收类",L13="非标固收类"),EOMONTH($A$2,A13*12),"") | Y13: ==VLOOKUP(资产明细!K13,配置调整!$B$4:$C$29,2,0) -> 0.06 | Z13: Govt | AC13: A Shares | AD13: ==P13 -> 267518.43 | AM13: ==IF(OR(L13="标准固收类",L13="非标固收类"),Y13,"") | BF13: ==AM13 | BG13: ==IF(OR(L13="标准固收类",L13="非标固收类"),"",MIN(Y13,2%)) -> 0.02 | BH13: 0 | BI13: 0.85
B14: H股 | C14: H股 | D14: 传统账户 | E14: 权益类 | F14: 上市普通股票 | G14: H股 | I14: Generic_H股 | J14: AFS | K14: H股 | L14: 权益类 | M14: ==IF($D14=配置调整!$A$5,VLOOKUP($K14,配置调整!$B$4:$O$29,6,0)*配置调整!$A$6,IF($D14=配置调整!$A$8,VLOOKUP($K14,配置调整!$B$4:$O$29,6,0)*配置调整!$A$9,IF($D14=配置调整!$A$11,VLOOKUP($K14,配置调整!$B$4:$O$29,6,0)*配置调整!$A$12,FALSE))) -> 90343545 | N14: ==M14 -> 90343545 | O14: 0 | P14: ==M14 -> 90343545 | Q14: ==M14 -> 90343545 | R14: ==M14 -> 90343545 | S14: 0 | U14: ==IF(OR(L14="标准固收类",L14="非标固收类"),$A$2,"") | V14: ==IF(OR(L14="标准固收类",L14="非标固收类"),EOMONTH($A$2,12),"") | W14: ==IF(OR(L14="标准固收类",L14="非标固收类"),EOMONTH($A$2,A14*12),"") | Y14: ==VLOOKUP(资产明细!K14,配置调整!$B$4:$C$29,2,0) -> 0.07 | Z14: Govt | AC14: H Shares | AD14: ==P14 -> 90343545 | AM14: ==IF(OR(L14="标准固收类",L14="非标固收类"),Y14,"") | BF14: ==AM14 | BG14: ==IF(OR(L14="标准固收类",L14="非标固收类"),"",MIN(Y14,2%)) -> 0.02 | BH14: 0 | BI14: 0.85
B15: MSCI发达市场 | C15: MSCI发达市场 | D15: 传统账户 | E15: 权益类 | F15: 上市普通股票 | G15: MSCI发达市场 | I15: Generic_MSCI发达市场 | J15: AFS | K15: MSCI发达市场 | L15: 权益类 | M15: ==IF($D15=配置调整!$A$5,VLOOKUP($K15,配置调整!$B$4:$O$29,6,0)*配置调整!$A$6,IF($D15=配置调整!$A$8,VLOOKUP($K15,配置调整!$B$4:$O$29,6,0)*配置调整!$A$9,IF($D15=配置调整!$A$11,VLOOKUP($K15,配置调整!$B$4:$O$29,6,0)*配置调整!$A$12,FALSE))) -> 1.2721636e+08 | N15: ==M15 -> 1.2721636e+08 | O15: 0 | P15: ==M15 -> 1.2721636e+08 | Q15: ==M15 -> 1.2721636e+08 | R15: ==M15 -> 1.2721636e+08 | S15: 0 | U15: ==IF(OR(L15="标准固收类",L15="非标固收类"),$A$2,"") | V15: ==IF(OR(L15="标准固收类",L15="非标固收类"),EOMONTH($A$2,12),"") | W15: ==IF(OR(L15="标准固收类",L15="非标固收类"),EOMONTH($A$2,A15*12),"") | Y15: ==VLOOKUP(资产明细!K15,配置调整!$B$4:$C$29,2,0) -> 0.08 | Z15: Govt | AC15: MSCI DM Shares | AD15: ==P15 -> 1.2721636e+08 | AM15: ==IF(OR(L15="标准固收类",L15="非标固收类"),Y15,"") | BF15: ==AM15 | BG15: ==IF(OR(L15="标准固收类",L15="非标固收类"),"",MIN(Y15,2%)) -> 0.02 | BH15: 0 | BI15: 0.85
B16: MSCI新兴市场 | C16: MSCI新兴市场 | D16: 传统账户 | E16: 权益类 | F16: 上市普通股票 | G16: MSCI新兴市场 | I16: Generic_MSCI新兴市场 | J16: AFS | K16: MSCI新兴市场 | L16: 权益类 | M16: ==IF($D16=配置调整!$A$5,VLOOKUP($K16,配置调整!$B$4:$O$29,6,0)*配置调整!$A$6,IF($D16=配置调整!$A$8,VLOOKUP($K16,配置调整!$B$4:$O$29,6,0)*配置调整!$A$9,IF($D16=配置调整!$A$11,VLOOKUP($K16,配置调整!$B$4:$O$29,6,0)*配置调整!$A$12,FALSE))) -> 6.7889524e+08 | N16: ==M16 -> 6.7889524e+08 | O16: 0 | P16: ==M16 -> 6.7889524e+08 | Q16: ==M16 -> 6.7889524e+08 | R16: ==M16 -> 6.7889524e+08 | S16: 0 | U16: ==IF(OR(L16="标准固收类",L16="非标固收类"),$A$2,"") | V16: ==IF(OR(L16="标准固收类",L16="非标固收类"),EOMONTH($A$2,12),"") | W16: ==IF(OR(L16="标准固收类",L16="非标固收类"),EOMONTH($A$2,A16*12),"") | Y16: ==VLOOKUP(资产明细!K16,配置调整!$B$4:$C$29,2,0) -> 0.085 | Z16: Govt | AC16: MSCI EM Shares | AD16: ==P16 -> 6.7889524e+08 | AM16: ==IF(OR(L16="标准固收类",L16="非标固收类"),Y16,"") | BF16: ==AM16 | BG16: ==IF(OR(L16="标准固收类",L16="非标固收类"),"",MIN(Y16,2%)) -> 0.02 | BH16: 0 | BI16: 0.85
B17: 债券基金 | C17: 债券基金 | D17: 传统账户 | E17: 权益类 | F17: 债券基金 | G17: 债券基金 | I17: Generic_债券基金 | J17: AFS | K17: 债券基金 | L17: 权益类 | M17: ==IF($D17=配置调整!$A$5,VLOOKUP($K17,配置调整!$B$4:$O$29,6,0)*配置调整!$A$6,IF($D17=配置调整!$A$8,VLOOKUP($K17,配置调整!$B$4:$O$29,6,0)*配置调整!$A$9,IF($D17=配置调整!$A$11,VLOOKUP($K17,配置调整!$B$4:$O$29,6,0)*配置调整!$A$12,FALSE))) -> 267518.43 | N17: ==M17 -> 267518.43 | O17: 0 | P17: ==M17 -> 267518.43 | Q17: ==M17 -> 267518.43 | R17: ==M17 -> 267518.43 | S17: 0 | U17: ==IF(OR(L17="标准固收类",L17="非标固收类"),$A$2,"") | V17: ==IF(OR(L17="标准固收类",L17="非标固收类"),EOMONTH($A$2,12),"") | W17: ==IF(OR(L17="标准固收类",L17="非标固收类"),EOMONTH($A$2,A17*12),"") | Y17: ==VLOOKUP(资产明细!K17,配置调整!$B$4:$C$29,2,0) -> 0.028487288 | Z17: Govt | AC17: FI Fund | AD17: ==P17 -> 267518.43 | AM17: ==IF(OR(L17="标准固收类",L17="非标固收类"),Y17,"") | BF17: ==AM17 | BG17: ==IF(OR(L17="标准固收类",L17="非标固收类"),"",MIN(Y17,2%)) -> 0.02 | BH17: 0 | BI17: 0.85
B18: 货币基金 | C18: 货币基金 | D18: 传统账户 | E18: 权益类 | F18: 货币基金 | G18: 货币基金 | I18: Generic_货币基金 | J18: AFS | K18: 货币基金 | L18: 权益类 | M18: ==IF($D18=配置调整!$A$5,VLOOKUP($K18,配置调整!$B$4:$O$29,6,0)*配置调整!$A$6,IF($D18=配置调整!$A$8,VLOOKUP($K18,配置调整!$B$4:$O$29,6,0)*配置调整!$A$9,IF($D18=配置调整!$A$11,VLOOKUP($K18,配置调整!$B$4:$O$29,6,0)*配置调整!$A$12,FALSE))) -> 267518.43 | N18: ==M18 -> 267518.43 | O18: 0 | P18: ==M18 -> 267518.43 | Q18: ==M18 -> 267518.43 | R18: ==M18 -> 267518.43 | S18: 0 | U18: ==IF(OR(L18="标准固收类",L18="非标固收类"),$A$2,"") | V18: ==IF(OR(L18="标准固收类",L18="非标固收类"),EOMONTH($A$2,12),"") | W18: ==IF(OR(L18="标准固收类",L18="非标固收类"),EOMONTH($A$2,A18*12),"") | Y18: ==VLOOKUP(资产明细!K18,配置调整!$B$4:$C$29,2,0) -> 0.015 | Z18: Govt | AC18: Monetary Fund | AD18: ==P18 -> 267518.43 | AM18: ==IF(OR(L18="标准固收类",L18="非标固收类"),Y18,"") | BF18: ==AM18 | BG18: ==IF(OR(L18="标准固收类",L18="非标固收类"),"",MIN(Y18,2%)) -> 0.015 | BH18: 0 | BI18: 0.85
B19: 混合基金 | C19: 混合基金 | D19: 传统账户 | E19: 权益类 | F19: 混合基金 | G19: 混合基金 | I19: Generic_混合基金 | J19: AFS | K19: 混合基金 | L19: 权益类 | M19: ==IF($D19=配置调整!$A$5,VLOOKUP($K19,配置调整!$B$4:$O$29,6,0)*配置调整!$A$6,IF($D19=配置调整!$A$8,VLOOKUP($K19,配置调整!$B$4:$O$29,6,0)*配置调整!$A$9,IF($D19=配置调整!$A$11,VLOOKUP($K19,配置调整!$B$4:$O$29,6,0)*配置调整!$A$12,FALSE))) -> 2.8761567e+08 | N19: ==M19 -> 2.8761567e+08 | O19: 0 | P19: ==M19 -> 2.8761567e+08 | Q19: ==M19 -> 2.8761567e+08 | R19: ==M19 -> 2.8761567e+08 | S19: 0 | U19: ==IF(OR(L19="标准固收类",L19="非标固收类"),$A$2,"") | V19: ==IF(OR(L19="标准固收类",L19="非标固收类"),EOMONTH($A$2,12),"") | W19: ==IF(OR(L19="标准固收类",L19="非标固收类"),EOMONTH($A$2,A19*12),"") | Y19: ==VLOOKUP(资产明细!K19,配置调整!$B$4:$C$29,2,0) -> 0.05 | Z19: Govt | AC19: Mixed Fund | AD19: ==P19 -> 2.8761567e+08 | AM19: ==IF(OR(L19="标准固收类",L19="非标固收类"),Y19,"") | BF19: ==AM19 | BG19: ==IF(OR(L19="标准固收类",L19="非标固收类"),"",MIN(Y19,2%)) -> 0.02 | BH19: 0 | BI19: 0.85
B20: 股票基金 | C20: 股票基金 | D20: 传统账户 | E20: 权益类 | F20: 股票基金 | G20: 股票基金 | I20: Generic_股票基金 | J20: AFS | K20: 股票基金 | L20: 权益类 | M20: ==IF($D20=配置调整!$A$5,VLOOKUP($K20,配置调整!$B$4:$O$29,6,0)*配置调整!$A$6,IF($D20=配置调整!$A$8,VLOOKUP($K20,配置调整!$B$4:$O$29,6,0)*配置调整!$A$9,IF($D20=配置调整!$A$11,VLOOKUP($K20,配置调整!$B$4:$O$29,6,0)*配置调整!$A$12,FALSE))) -> 267518.43 | N20: ==M20 -> 267518.43 | O20: 0 | P20: ==M20 -> 267518.43 | Q20: ==M20 -> 267518.43 | R20: ==M20 -> 267518.43 | S20: 0 | U20: ==IF(OR(L20="标准固收类",L20="非标固收类"),$A$2,"") | V20: ==IF(OR(L20="标准固收类",L20="非标固收类"),EOMONTH($A$2,12),"") | W20: ==IF(OR(L20="标准固收类",L20="非标固收类"),EOMONTH($A$2,A20*12),"") | Y20: ==VLOOKUP(资产明细!K20,配置调整!$B$4:$C$29,2,0) -> 0.055 | Z20: Govt | AC20: Equity Fund | AD20: ==P20 -> 267518.43 | AM20: ==IF(OR(L20="标准固收类",L20="非标固收类"),Y20,"") | BF20: ==AM20 | BG20: ==IF(OR(L20="标准固收类",L20="非标固收类"),"",Y20) -> 0.055 | BH20: 0 | BI20: 0.85
B21: 优先股 | C21: 优先股 | D21: 传统账户 | E21: 权益类 | F21: 优先股 | G21: 优先股 | I21: Generic_优先股 | J21: AFS | K21: 优先股 | L21: 权益类 | M21: ==IF($D21=配置调整!$A$5,VLOOKUP($K21,配置调整!$B$4:$O$29,6,0)*配置调整!$A$6,IF($D21=配置调整!$A$8,VLOOKUP($K21,配置调整!$B$4:$O$29,6,0)*配置调整!$A$9,IF($D21=配置调整!$A$11,VLOOKUP($K21,配置调整!$B$4:$O$29,6,0)*配置调整!$A$12,FALSE))) -> 267518.43 | N21: ==M21 -> 267518.43 | O21: 0 | P21: ==M21 -> 267518.43 | Q21: ==M21 -> 267518.43 | R21: ==M21 -> 267518.43 | S21: 0 | U21: ==IF(OR(L21="标准固收类",L21="非标固收类"),$A$2,"") | V21: ==IF(OR(L21="标准固收类",L21="非标固收类"),EOMONTH($A$2,12),"") | W21: ==IF(OR(L21="标准固收类",L21="非标固收类"),EOMONTH($A$2,A21*12),"") | Y21: ==VLOOKUP(资产明细!K21,配置调整!$B$4:$C$29,2,0) -> 0.043 | Z21: Govt | AC21: LT Equity | AD21: ==P21 -> 267518.43 | AM21: ==IF(OR(L21="标准固收类",L21="非标固收类"),Y21,"") | BF21: ==AM21 | BG21: ==IF(OR(L21="标准固收类",L21="非标固收类"),"",MIN(Y21,2%)) -> 0.02 | BH21: 0 | BI21: 0.85
B22: 长期股权投资 | C22: 长期股权投资 | D22: 传统账户 | E22: 权益类 | F22: 股权投资 | G22: 长期股权投资 | I22: Generic_长期股权投资 | J22: AFS | K22: 长期股权投资 | L22: 权益类 | M22: ==IF($D22=配置调整!$A$5,VLOOKUP($K22,配置调整!$B$4:$O$29,6,0)*配置调整!$A$6,IF($D22=配置调整!$A$8,VLOOKUP($K22,配置调整!$B$4:$O$29,6,0)*配置调整!$A$9,IF($D22=配置调整!$A$11,VLOOKUP($K22,配置调整!$B$4:$O$29,6,0)*配置调整!$A$12,FALSE))) -> 267518.43 | N22: ==M22 -> 267518.43 | O22: 0 | P22: ==M22 -> 267518.43 | Q22: ==M22 -> 267518.43 | R22: ==M22 -> 267518.43 | S22: 0 | U22: ==IF(OR(L22="标准固收类",L22="非标固收类"),$A$2,"") | V22: ==IF(OR(L22="标准固收类",L22="非标固收类"),EOMONTH($A$2,12),"") | W22: ==IF(OR(L22="标准固收类",L22="非标固收类"),EOMONTH($A$2,A22*12),"") | Y22: ==VLOOKUP(资产明细!K22,配置调整!$B$4:$C$29,2,0) -> 0.05 | Z22: Govt | AC22: LT Equity | AD22: ==P22 -> 267518.43 | AM22: ==IF(OR(L22="标准固收类",L22="非标固收类"),Y22,"") | BF22: ==AM22 | BG22: ==IF(OR(L22="标准固收类",L22="非标固收类"),"",MIN(Y22,2%)) -> 0.02 | BH22: 0 | BI22: 0.85
B23: 未上市股权 | C23: 未上市股权 | D23: 传统账户 | E23: 权益类 | F23: 股权投资 | G23: 未上市股权 | I23: Generic_未上市股权 | J23: AFS | K23: 未上市股权 | L23: 权益类 | M23: ==IF($D23=配置调整!$A$5,VLOOKUP($K23,配置调整!$B$4:$O$29,6,0)*配置调整!$A$6,IF($D23=配置调整!$A$8,VLOOKUP($K23,配置调整!$B$4:$O$29,6,0)*配置调整!$A$9,IF($D23=配置调整!$A$11,VLOOKUP($K23,配置调整!$B$4:$O$29,6,0)*配置调整!$A$12,FALSE))) -> 1.6745297e+08 | N23: ==M23 -> 1.6745297e+08 | O23: 0 | P23: ==M23 -> 1.6745297e+08 | Q23: ==M23 -> 1.6745297e+08 | R23: ==M23 -> 1.6745297e+08 | S23: 0 | U23: ==IF(OR(L23="标准固收类",L23="非标固收类"),$A$2,"") | V23: ==IF(OR(L23="标准固收类",L23="非标固收类"),EOMONTH($A$2,12),"") | W23: ==IF(OR(L23="标准固收类",L23="非标固收类"),EOMONTH($A$2,A23*12),"") | Y23: ==VLOOKUP(资产明细!K23,配置调整!$B$4:$C$29,2,0) -> 0.086 | Z23: Govt | AC23: LT Equity | AD23: ==P23 -> 1.6745297e+08 | AM23: ==IF(OR(L23="标准固收类",L23="非标固收类"),Y23,"") | BF23: ==AM23 | BG23: ==IF(OR(L23="标准固收类",L23="非标固收类"),"",MIN(Y23,2%)) -> 0.02 | BH23: 0 | BI23: 0.85
B24: 固收产品 | C24: 固收产品 | D24: 传统账户 | E24: 固定收益类 | F24: 固收产品 | G24: 固收产品 | I24: Generic_固收产品 | J24: AFS | K24: 固收产品 | L24: 权益类 | M24: ==IF($D24=配置调整!$A$5,VLOOKUP($K24,配置调整!$B$4:$O$29,6,0)*配置调整!$A$6,IF($D24=配置调整!$A$8,VLOOKUP($K24,配置调整!$B$4:$O$29,6,0)*配置调整!$A$9,IF($D24=配置调整!$A$11,VLOOKUP($K24,配置调整!$B$4:$O$29,6,0)*配置调整!$A$12,FALSE))) -> 2.6877295e+09 | N24: ==M24 -> 2.6877295e+09 | O24: 0 | P24: ==M24 -> 2.6877295e+09 | Q24: ==M24 -> 2.6877295e+09 | R24: ==M24 -> 2.6877295e+09 | S24: 0 | U24: ==IF(OR(L24="标准固收类",L24="非标固收类"),$A$2,"") | V24: ==IF(OR(L24="标准固收类",L24="非标固收类"),EOMONTH($A$2,12),"") | W24: ==IF(OR(L24="标准固收类",L24="非标固收类"),EOMONTH($A$2,A24*12),"") | Y24: ==VLOOKUP(资产明细!K24,配置调整!$B$4:$C$29,2,0) -> 0.03481604 | Z24: Govt | AC24: FI Fund | AD24: ==P24 -> 2.6877295e+09 | AM24: ==IF(OR(L24="标准固收类",L24="非标固收类"),Y24,"") | BF24: ==AM24 | BG24: ==IF(OR(L24="标准固收类",L24="非标固收类"),"",MIN(Y24,2%)) -> 0.02 | BH24: 0 | BI24: 0.85
B25: 现金类 | C25: 现金类 | D25: 传统账户 | E25: 现金类 | F25: 现金类 | G25: 现金类 | I25: Generic_现金类 | J25: AFS | K25: 现金类 | L25: 现金类 | M25: ==IF($D25=配置调整!$A$5,VLOOKUP($K25,配置调整!$B$4:$O$29,6,0)*配置调整!$A$6,IF($D25=配置调整!$A$8,VLOOKUP($K25,配置调整!$B$4:$O$29,6,0)*配置调整!$A$9,IF($D25=配置调整!$A$11,VLOOKUP($K25,配置调整!$B$4:$O$29,6,0)*配置调整!$A$12,FALSE))) -> 8.2994137e+08 | N25: ==M25 -> 8.2994137e+08 | O25: 0 | P25: ==M25 -> 8.2994137e+08 | Q25: ==M25 -> 8.2994137e+08 | R25: ==M25 -> 8.2994137e+08 | S25: 0 | U25: ==IF(OR(L25="标准固收类",L25="非标固收类"),$A$2,"") | V25: ==IF(OR(L25="标准固收类",L25="非标固收类"),EOMONTH($A$2,12),"") | W25: ==IF(OR(L25="标准固收类",L25="非标固收类"),EOMONTH($A$2,A25*12),"") | Y25: ==VLOOKUP(资产明细!K25,配置调整!$B$4:$C$29,2,0) -> 0.015 | Z25: Govt | AD25: ==P25 -> 8.2994137e+08 | AM25: ==IF(OR(L25="标准固收类",L25="非标固收类"),Y25,"") | BF25: ==AM25 | BG25: ==IF(OR(L25="标准固收类",L25="非标固收类"),"",MIN(Y25,2%)) -> 0.015 | BH25: 0 | BI25: 0.85
A26: 3 | B26: 其他信用产品 | C26: 其他信用产品 | D26: 传统账户 | E26: 固定收益类 | F26: 其他信用产品 | G26: 其他信用产品 | I26: Generic_其他信用产品 | J26: AFS | K26: 其他信用产品 | L26: 标准固收类 | M26: ==IF($D26=配置调整!$A$5,VLOOKUP($K26,配置调整!$B$4:$O$29,6,0)*配置调整!$A$6,IF($D26=配置调整!$A$8,VLOOKUP($K26,配置调整!$B$4:$O$29,6,0)*配置调整!$A$9,IF($D26=配置调整!$A$11,VLOOKUP($K26,配置调整!$B$4:$O$29,6,0)*配置调整!$A$12,FALSE))) -> 3.2773084e+09 | N26: ==M26 -> 3.2773084e+09 | O26: 0 | P26: ==M26 -> 3.2773084e+09 | Q26: ==M26 -> 3.2773084e+09 | R26: ==M26 -> 3.2773084e+09 | S26: 0 | T26: 1 | U26: ==IF(OR(L26="标准固收类",L26="非标固收类"),$A$2,"") -> 45657 | V26: ==IF(OR(L26="标准固收类",L26="非标固收类"),EOMONTH($A$2,12),"") -> 46022 | W26: ==IF(OR(L26="标准固收类",L26="非标固收类"),EOMONTH($A$2,A26*12),"") -> 46752 | X26: 不适用 | Y26: ==VLOOKUP(资产明细!K26,配置调整!$B$4:$C$29,2,0) -> 0.031651664 | Z26: Govt | AA26: MTNIG3+ | AD26: ==P26 -> 3.2773084e+09 | AM26: ==IF(OR(L26="标准固收类",L26="非标固收类"),Y26,"") -> 0.031651664 | BF26: ==AM26 -> 0.031651664 | BG26: ==IF(OR(L26="标准固收类",L26="非标固收类"),"",MIN(Y26,2%)) | BH26: 0 | BI26: 0.85
A27: 5 | B27: 存款 | C27: 存款 | D27: 传统账户 | E27: 固定收益类 | F27: 存款 | G27: 存款 | I27: Generic_存款 | J27: AFS | K27: 存款 | L27: 标准固收类 | M27: ==IF($D27=配置调整!$A$5,VLOOKUP($K27,配置调整!$B$4:$O$29,6,0)*配置调整!$A$6,IF($D27=配置调整!$A$8,VLOOKUP($K27,配置调整!$B$4:$O$29,6,0)*配置调整!$A$9,IF($D27=配置调整!$A$11,VLOOKUP($K27,配置调整!$B$4:$O$29,6,0)*配置调整!$A$12,FALSE))) -> 1.2022584e+09 | N27: ==M27 -> 1.2022584e+09 | O27: 0 | P27: ==M27 -> 1.2022584e+09 | Q27: ==M27 -> 1.2022584e+09 | R27: ==M27 -> 1.2022584e+09 | S27: 0 | T27: 1 | U27: ==IF(OR(L27="标准固收类",L27="非标固收类"),$A$2,"") -> 45657 | V27: ==IF(OR(L27="标准固收类",L27="非标固收类"),EOMONTH($A$2,12),"") -> 46022 | W27: ==IF(OR(L27="标准固收类",L27="非标固收类"),EOMONTH($A$2,A27*12),"") -> 47483 | X27: 不适用 | Y27: ==VLOOKUP(资产明细!K27,配置调整!$B$4:$C$29,2,0) -> 0.028 | Z27: Govt | AA27: CORIG0-3 | AD27: ==P27 -> 1.2022584e+09 | AM27: ==IF(OR(L27="标准固收类",L27="非标固收类"),Y27,"") -> 0.028 | BF27: ==AM27 -> 0.028 | BG27: ==IF(OR(L27="标准固收类",L27="非标固收类"),"",MIN(Y27,2%)) | BH27: 0 | BI27: 0.85
B28: 不动产 | C28: 不动产 | D28: 传统账户 | E28: 不动产 | F28: 不动产 | G28: 不动产 | I28: Generic_不动产 | J28: AFS | K28: 不动产 | L28: 权益类 | M28: ==IF($D28=配置调整!$A$5,VLOOKUP($K28,配置调整!$B$4:$O$29,6,0)*配置调整!$A$6,IF($D28=配置调整!$A$8,VLOOKUP($K28,配置调整!$B$4:$O$29,6,0)*配置调整!$A$9,IF($D28=配置调整!$A$11,VLOOKUP($K28,配置调整!$B$4:$O$29,6,0)*配置调整!$A$12,FALSE))) -> 2.6119919e+09 | N28: ==M28 -> 2.6119919e+09 | O28: 0 | P28: ==M28 -> 2.6119919e+09 | Q28: ==M28 -> 2.6119919e+09 | R28: ==M28 -> 2.6119919e+09 | S28: 0 | U28: ==IF(OR(L28="标准固收类",L28="非标固收类"),$A$2,"") | V28: ==IF(OR(L28="标准固收类",L28="非标固收类"),EOMONTH($A$2,12),"") | W28: ==IF(OR(L28="标准固收类",L28="非标固收类"),EOMONTH($A$2,A28*12),"") | Y28: ==VLOOKUP(资产明细!K28,配置调整!$B$4:$C$29,2,0) -> 0.065 | Z28: Govt | AC28: Real Estate Index | AD28: ==P28 -> 2.6119919e+09 | AM28: ==IF(OR(L28="标准固收类",L28="非标固收类"),Y28,"") | BF28: ==AM28 | BG28: ==IF(OR(L28="标准固收类",L28="非标固收类"),"",MIN(Y28,2%)) -> 0.02 | BH28: 0 | BI28: 0.85
A29: 3 | B29: 国债_3Y2 | C29: 国债_3Y | D29: 万能账户 | E29: 固定收益类 | F29: 国债 | G29: 国债_3Y | I29: Generic_国债_3Y | J29: AFS | K29: 国债_3Y | L29: 标准固收类 | M29: ==IF($D29=配置调整!$A$5,VLOOKUP($K29,配置调整!$B$4:$O$29,6,0)*配置调整!$A$6,IF($D29=配置调整!$A$8,VLOOKUP($K29,配置调整!$B$4:$O$29,6,0)*配置调整!$A$9,IF($D29=配置调整!$A$11,VLOOKUP($K29,配置调整!$B$4:$O$29,6,0)*配置调整!$A$12,FALSE))) -> 98950474 | N29: ==M29 -> 98950474 | O29: 0 | P29: ==M29 -> 98950474 | Q29: ==M29 -> 98950474 | R29: ==M29 -> 98950474 | S29: 0 | T29: 1 | U29: ==IF(OR(L29="标准固收类",L29="非标固收类"),$A$2,"") -> 45657 | V29: ==IF(OR(L29="标准固收类",L29="非标固收类"),EOMONTH($A$2,12),"") -> 46022 | W29: ==IF(OR(L29="标准固收类",L29="非标固收类"),EOMONTH($A$2,A29*12),"") -> 46752 | X29: 不适用 | Y29: ==VLOOKUP(资产明细!K29,配置调整!$B$4:$C$29,2,0) -> 0.011872 | Z29: Govt | AD29: ==P29 -> 98950474 | AM29: ==IF(OR(L29="标准固收类",L29="非标固收类"),Y29,"") -> 0.011872 | BF29: ==AM29 -> 0.011872 | BG29: ==IF(OR(L29="标准固收类",L29="非标固收类"),"",MIN(Y29,2%)) | BH29: 0 | BI29: 0.85
A30: 5 | B30: 国债_5Y2 | C30: 国债_5Y | D30: 万能账户 | E30: 固定收益类 | F30: 国债 | G30: 国债_5Y | I30: Generic_国债_5Y | J30: AFS | K30: 国债_5Y | L30: 标准固收类 | M30: ==IF($D30=配置调整!$A$5,VLOOKUP($K30,配置调整!$B$4:$O$29,6,0)*配置调整!$A$6,IF($D30=配置调整!$A$8,VLOOKUP($K30,配置调整!$B$4:$O$29,6,0)*配置调整!$A$9,IF($D30=配置调整!$A$11,VLOOKUP($K30,配置调整!$B$4:$O$29,6,0)*配置调整!$A$12,FALSE))) -> 2.0840971e+08 | N30: ==M30 -> 2.0840971e+08 | O30: 0 | P30: ==M30 -> 2.0840971e+08 | Q30: ==M30 -> 2.0840971e+08 | R30: ==M30 -> 2.0840971e+08 | S30: 0 | T30: 1 | U30: ==IF(OR(L30="标准固收类",L30="非标固收类"),$A$2,"") -> 45657 | V30: ==IF(OR(L30="标准固收类",L30="非标固收类"),EOMONTH($A$2,12),"") -> 46022 | W30: ==IF(OR(L30="标准固收类",L30="非标固收类"),EOMONTH($A$2,A30*12),"") -> 47483 | X30: 不适用 | Y30: ==VLOOKUP(资产明细!K30,配置调整!$B$4:$C$29,2,0) -> 0.014152 | Z30: Govt | AD30: ==P30 -> 2.0840971e+08 | AM30: ==IF(OR(L30="标准固收类",L30="非标固收类"),Y30,"") -> 0.014152 | BF30: ==AM30 -> 0.014152 | BG30: ==IF(OR(L30="标准固收类",L30="非标固收类"),"",MIN(Y30,2%)) | BH30: 0 | BI30: 0.85
A31: 10 | B31: 国债_10Y2 | C31: 国债_10Y | D31: 万能账户 | E31: 固定收益类 | F31: 国债 | G31: 国债_10Y | I31: Generic_国债_10Y | J31: AFS | K31: 国债_10Y | L31: 标准固收类 | M31: ==IF($D31=配置调整!$A$5,VLOOKUP($K31,配置调整!$B$4:$O$29,6,0)*配置调整!$A$6,IF($D31=配置调整!$A$8,VLOOKUP($K31,配置调整!$B$4:$O$29,6,0)*配置调整!$A$9,IF($D31=配置调整!$A$11,VLOOKUP($K31,配置调整!$B$4:$O$29,6,0)*配置调整!$A$12,FALSE))) -> 8.6934539e+08 | N31: ==M31 -> 8.6934539e+08 | O31: 0 | P31: ==M31 -> 8.6934539e+08 | Q31: ==M31 -> 8.6934539e+08 | R31: ==M31 -> 8.6934539e+08 | S31: 0 | T31: 1 | U31: ==IF(OR(L31="标准固收类",L31="非标固收类"),$A$2,"") -> 45657 | V31: ==IF(OR(L31="标准固收类",L31="非标固收类"),EOMONTH($A$2,12),"") -> 46022 | W31: ==IF(OR(L31="标准固收类",L31="非标固收类"),EOMONTH($A$2,A31*12),"") -> 49309 | X31: 不适用 | Y31: ==VLOOKUP(资产明细!K31,配置调整!$B$4:$C$29,2,0) -> 0.016752 | Z31: Govt | AD31: ==P31 -> 8.6934539e+08 | AM31: ==IF(OR(L31="标准固收类",L31="非标固收类"),Y31,"") -> 0.016752 | BF31: ==AM31 -> 0.016752 | BG31: ==IF(OR(L31="标准固收类",L31="非标固收类"),"",MIN(Y31,2%)) | BH31: 0 | BI31: 0.85
A32: 20 | B32: 国债_20Y2 | C32: 国债_20Y | D32: 万能账户 | E32: 固定收益类 | F32: 国债 | G32: 国债_20Y | I32: Generic_国债_20Y | J32: AFS | K32: 国债_20Y | L32: 标准固收类 | M32: ==IF($D32=配置调整!$A$5,VLOOKUP($K32,配置调整!$B$4:$O$29,6,0)*配置调整!$A$6,IF($D32=配置调整!$A$8,VLOOKUP($K32,配置调整!$B$4:$O$29,6,0)*配置调整!$A$9,IF($D32=配置调整!$A$11,VLOOKUP($K32,配置调整!$B$4:$O$29,6,0)*配置调整!$A$12,FALSE))) -> 3.8019957e+09 | N32: ==M32 -> 3.8019957e+09 | O32: 0 | P32: ==M32 -> 3.8019957e+09 | Q32: ==M32 -> 3.8019957e+09 | R32: ==M32 -> 3.8019957e+09 | S32: 0 | T32: 1 | U32: ==IF(OR(L32="标准固收类",L32="非标固收类"),$A$2,"") -> 45657 | V32: ==IF(OR(L32="标准固收类",L32="非标固收类"),EOMONTH($A$2,12),"") -> 46022 | W32: ==IF(OR(L32="标准固收类",L32="非标固收类"),EOMONTH($A$2,A32*12),"") -> 52962 | X32: 不适用 | Y32: ==VLOOKUP(资产明细!K32,配置调整!$B$4:$C$29,2,0) -> 0.019747 | Z32: Govt | AD32: ==P32 -> 3.8019957e+09 | AM32: ==IF(OR(L32="标准固收类",L32="非标固收类"),Y32,"") -> 0.019747 | BF32: ==AM32 -> 0.019747 | BG32: ==IF(OR(L32="标准固收类",L32="非标固收类"),"",MIN(Y32,2%)) | BH32: 0 | BI32: 0.85
A33: 50 | B33: 国债_50Y2 | C33: 国债_50Y | D33: 万能账户 | E33: 固定收益类 | F33: 国债 | G33: 国债_50Y | I33: Generic_国债_50Y | J33: AFS | K33: 国债_50Y | L33: 标准固收类 | M33: ==IF($D33=配置调整!$A$5,VLOOKUP($K33,配置调整!$B$4:$O$29,6,0)*配置调整!$A$6,IF($D33=配置调整!$A$8,VLOOKUP($K33,配置调整!$B$4:$O$29,6,0)*配置调整!$A$9,IF($D33=配置调整!$A$11,VLOOKUP($K33,配置调整!$B$4:$O$29,6,0)*配置调整!$A$12,FALSE))) -> 5.5148303e+09 | N33: ==M33 -> 5.5148303e+09 | O33: 0 | P33: ==M33 -> 5.5148303e+09 | Q33: ==M33 -> 5.5148303e+09 | R33: ==M33 -> 5.5148303e+09 | S33: 0 | T33: 1 | U33: ==IF(OR(L33="标准固收类",L33="非标固收类"),$A$2,"") -> 45657 | V33: ==IF(OR(L33="标准固收类",L33="非标固收类"),EOMONTH($A$2,12),"") -> 46022 | W33: ==IF(OR(L33="标准固收类",L33="非标固收类"),EOMONTH($A$2,A33*12),"") -> 63919 | X33: 不适用 | Y33: ==VLOOKUP(资产明细!K33,配置调整!$B$4:$C$29,2,0) -> 0.019875 | Z33: Govt | AD33: ==P33 -> 5.5148303e+09 | AM33: ==IF(OR(L33="标准固收类",L33="非标固收类"),Y33,"") -> 0.019875 | BF33: ==AM33 -> 0.019875 | BG33: ==IF(OR(L33="标准固收类",L33="非标固收类"),"",MIN(Y33,2%)) | BH33: 0 | BI33: 0.85
A34: 3 | B34: 高等级信用债_3Y2 | C34: 高等级信用债_3Y | D34: 万能账户 | E34: 固定收益类 | F34: 高等级信用债 | G34: 高等级信用债_3Y | I34: Generic_高等级信用债_3Y | J34: AFS | K34: 信用债_3Y | L34: 标准固收类 | M34: ==IF($D34=配置调整!$A$5,VLOOKUP($K34,配置调整!$B$4:$O$29,6,0)*配置调整!$A$6,IF($D34=配置调整!$A$8,VLOOKUP($K34,配置调整!$B$4:$O$29,6,0)*配置调整!$A$9,IF($D34=配置调整!$A$11,VLOOKUP($K34,配置调整!$B$4:$O$29,6,0)*配置调整!$A$12,FALSE))) -> 1.8185257e+09 | N34: ==M34 -> 1.8185257e+09 | O34: 0 | P34: ==M34 -> 1.8185257e+09 | Q34: ==M34 -> 1.8185257e+09 | R34: ==M34 -> 1.8185257e+09 | S34: 0 | T34: 1 | U34: ==IF(OR(L34="标准固收类",L34="非标固收类"),$A$2,"") -> 45657 | V34: ==IF(OR(L34="标准固收类",L34="非标固收类"),EOMONTH($A$2,12),"") -> 46022 | W34: ==IF(OR(L34="标准固收类",L34="非标固收类"),EOMONTH($A$2,A34*12),"") -> 46752 | X34: 不适用 | Y34: ==VLOOKUP(资产明细!K34,配置调整!$B$4:$C$29,2,0) -> 0.017501 | Z34: Govt | AA34: CORIG0-3 | AD34: ==P34 -> 1.8185257e+09 | AM34: ==IF(OR(L34="标准固收类",L34="非标固收类"),Y34,"") -> 0.017501 | BF34: ==AM34 -> 0.017501 | BG34: ==IF(OR(L34="标准固收类",L34="非标固收类"),"",MIN(Y34,2%)) | BH34: 0 | BI34: 0.85
A35: 5 | B35: 高等级信用债_5Y2 | C35: 高等级信用债_5Y | D35: 万能账户 | E35: 固定收益类 | F35: 高等级信用债 | G35: 高等级信用债_5Y | I35: Generic_高等级信用债_5Y | J35: AFS | K35: 信用债_5Y | L35: 标准固收类 | M35: ==IF($D35=配置调整!$A$5,VLOOKUP($K35,配置调整!$B$4:$O$29,6,0)*配置调整!$A$6,IF($D35=配置调整!$A$8,VLOOKUP($K35,配置调整!$B$4:$O$29,6,0)*配置调整!$A$9,IF($D35=配置调整!$A$11,VLOOKUP($K35,配置调整!$B$4:$O$29,6,0)*配置调整!$A$12,FALSE))) -> 1.5992956e+08 | N35: ==M35 -> 1.5992956e+08 | O35: 0 | P35: ==M35 -> 1.5992956e+08 | Q35: ==M35 -> 1.5992956e+08 | R35: ==M35 -> 1.5992956e+08 | S35: 0 | T35: 1 | U35: ==IF(OR(L35="标准固收类",L35="非标固收类"),$A$2,"") -> 45657 | V35: ==IF(OR(L35="标准固收类",L35="非标固收类"),EOMONTH($A$2,12),"") -> 46022 | W35: ==IF(OR(L35="标准固收类",L35="非标固收类"),EOMONTH($A$2,A35*12),"") -> 47483 | X35: 不适用 | Y35: ==VLOOKUP(资产明细!K35,配置调整!$B$4:$C$29,2,0) -> 0.018727 | Z35: Govt | AA35: CORIG3+ | AD35: ==P35 -> 1.5992956e+08 | AM35: ==IF(OR(L35="标准固收类",L35="非标固收类"),Y35,"") -> 0.018727 | BF35: ==AM35 -> 0.018727 | BG35: ==IF(OR(L35="标准固收类",L35="非标固收类"),"",MIN(Y35,2%)) | BH35: 0 | BI35: 0.85
A36: 10 | B36: 高等级信用债_10Y2 | C36: 高等级信用债_10Y | D36: 万能账户 | E36: 固定收益类 | F36: 高等级信用债 | G36: 高等级信用债_10Y | I36: Generic_高等级信用债_10Y | J36: AFS | K36: 信用债_10Y | L36: 标准固收类 | M36: ==IF($D36=配置调整!$A$5,VLOOKUP($K36,配置调整!$B$4:$O$29,6,0)*配置调整!$A$6,IF($D36=配置调整!$A$8,VLOOKUP($K36,配置调整!$B$4:$O$29,6,0)*配置调整!$A$9,IF($D36=配置调整!$A$11,VLOOKUP($K36,配置调整!$B$4:$O$29,6,0)*配置调整!$A$12,FALSE))) -> 1.0469498e+09 | N36: ==M36 -> 1.0469498e+09 | O36: 0 | P36: ==M36 -> 1.0469498e+09 | Q36: ==M36 -> 1.0469498e+09 | R36: ==M36 -> 1.0469498e+09 | S36: 0 | T36: 1 | U36: ==IF(OR(L36="标准固收类",L36="非标固收类"),$A$2,"") -> 45657 | V36: ==IF(OR(L36="标准固收类",L36="非标固收类"),EOMONTH($A$2,12),"") -> 46022 | W36: ==IF(OR(L36="标准固收类",L36="非标固收类"),EOMONTH($A$2,A36*12),"") -> 49309 | X36: 不适用 | Y36: ==VLOOKUP(资产明细!K36,配置调整!$B$4:$C$29,2,0) -> 0.021173 | Z36: Govt | AA36: CORIG3+ | AD36: ==P36 -> 1.0469498e+09 | AM36: ==IF(OR(L36="标准固收类",L36="非标固收类"),Y36,"") -> 0.021173 | BF36: ==AM36 -> 0.021173 | BG36: ==IF(OR(L36="标准固收类",L36="非标固收类"),"",MIN(Y36,2%)) | BH36: 0 | BI36: 0.85
A37: 3 | B37: 非标资产_3Y2 | C37: 非标资产_3Y | D37: 万能账户 | E37: 固定收益类 | F37: 非标资产 | G37: 非标资产_3Y | I37: Generic_非标资产_3Y | J37: AFS | K37: 非标资产_3Y | L37: 非标固收类 | M37: ==IF($D37=配置调整!$A$5,VLOOKUP($K37,配置调整!$B$4:$O$29,6,0)*配置调整!$A$6,IF($D37=配置调整!$A$8,VLOOKUP($K37,配置调整!$B$4:$O$29,6,0)*配置调整!$A$9,IF($D37=配置调整!$A$11,VLOOKUP($K37,配置调整!$B$4:$O$29,6,0)*配置调整!$A$12,FALSE))) -> 7.6756732e+08 | N37: ==M37 -> 7.6756732e+08 | O37: 0 | P37: ==M37 -> 7.6756732e+08 | Q37: ==M37 -> 7.6756732e+08 | R37: ==M37 -> 7.6756732e+08 | S37: 0 | T37: 1 | U37: ==IF(OR(L37="标准固收类",L37="非标固收类"),$A$2,"") -> 45657 | V37: ==IF(OR(L37="标准固收类",L37="非标固收类"),EOMONTH($A$2,12),"") -> 46022 | W37: ==IF(OR(L37="标准固收类",L37="非标固收类"),EOMONTH($A$2,A37*12),"") -> 46752 | X37: 不适用 | Y37: ==VLOOKUP(资产明细!K37,配置调整!$B$4:$C$29,2,0) -> 0.024290322 | Z37: Govt | AA37: CORIG3+ | AB37: IP 3Y | AD37: ==P37 -> 7.6756732e+08 | AM37: ==IF(OR(L37="标准固收类",L37="非标固收类"),Y37,"") -> 0.024290322 | BF37: ==AM37 -> 0.024290322 | BG37: ==IF(OR(L37="标准固收类",L37="非标固收类"),"",MIN(Y37,2%)) | BH37: 0 | BI37: 0.85
A38: 5 | B38: 非标资产_5Y2 | C38: 非标资产_5Y | D38: 万能账户 | E38: 固定收益类 | F38: 非标资产 | G38: 非标资产_5Y | I38: Generic_非标资产_5Y | J38: AFS | K38: 非标资产_5Y | L38: 非标固收类 | M38: ==IF($D38=配置调整!$A$5,VLOOKUP($K38,配置调整!$B$4:$O$29,6,0)*配置调整!$A$6,IF($D38=配置调整!$A$8,VLOOKUP($K38,配置调整!$B$4:$O$29,6,0)*配置调整!$A$9,IF($D38=配置调整!$A$11,VLOOKUP($K38,配置调整!$B$4:$O$29,6,0)*配置调整!$A$12,FALSE))) -> 5.0298086e+08 | N38: ==M38 -> 5.0298086e+08 | O38: 0 | P38: ==M38 -> 5.0298086e+08 | Q38: ==M38 -> 5.0298086e+08 | R38: ==M38 -> 5.0298086e+08 | S38: 0 | T38: 1 | U38: ==IF(OR(L38="标准固收类",L38="非标固收类"),$A$2,"") -> 45657 | V38: ==IF(OR(L38="标准固收类",L38="非标固收类"),EOMONTH($A$2,12),"") -> 46022 | W38: ==IF(OR(L38="标准固收类",L38="非标固收类"),EOMONTH($A$2,A38*12),"") -> 47483 | X38: 不适用 | Y38: ==VLOOKUP(资产明细!K38,配置调整!$B$4:$C$29,2,0) -> 0.025629035 | Z38: Govt | AA38: CORIG3+ | AB38: IP 5Y | AD38: ==P38 -> 5.0298086e+08 | AM38: ==IF(OR(L38="标准固收类",L38="非标固收类"),Y38,"") -> 0.025629035 | BF38: ==AM38 -> 0.025629035 | BG38: ==IF(OR(L38="标准固收类",L38="非标固收类"),"",MIN(Y38,2%)) | BH38: 0 | BI38: 0.85
B39: A股2 | C39: A股 | D39: 万能账户 | E39: 权益类 | F39: 上市普通股票 | G39: A股 | I39: Generic_A股 | J39: AFS | K39: A股 | L39: 权益类 | M39: ==IF($D39=配置调整!$A$5,VLOOKUP($K39,配置调整!$B$4:$O$29,6,0)*配置调整!$A$6,IF($D39=配置调整!$A$8,VLOOKUP($K39,配置调整!$B$4:$O$29,6,0)*配置调整!$A$9,IF($D39=配置调整!$A$11,VLOOKUP($K39,配置调整!$B$4:$O$29,6,0)*配置调整!$A$12,FALSE))) -> 267518.43 | N39: ==M39 -> 267518.43 | O39: 0 | P39: ==M39 -> 267518.43 | Q39: ==M39 -> 267518.43 | R39: ==M39 -> 267518.43 | S39: 0 | U39: ==IF(OR(L39="标准固收类",L39="非标固收类"),$A$2,"") | V39: ==IF(OR(L39="标准固收类",L39="非标固收类"),EOMONTH($A$2,12),"") | W39: ==IF(OR(L39="标准固收类",L39="非标固收类"),EOMONTH($A$2,A39*12),"") | Y39: ==VLOOKUP(资产明细!K39,配置调整!$B$4:$C$29,2,0) -> 0.06 | Z39: Govt | AC39: A Shares | AD39: ==P39 -> 267518.43 | AM39: ==IF(OR(L39="标准固收类",L39="非标固收类"),Y39,"") | BF39: ==AM39 | BG39: ==IF(OR(L39="标准固收类",L39="非标固收类"),"",MIN(Y39,2%)) -> 0.02 | BH39: 0 | BI39: 0.85
B40: H股2 | C40: H股 | D40: 万能账户 | E40: 权益类 | F40: 上市普通股票 | G40: H股 | I40: Generic_H股 | J40: AFS | K40: H股 | L40: 权益类 | M40: ==IF($D40=配置调整!$A$5,VLOOKUP($K40,配置调整!$B$4:$O$29,6,0)*配置调整!$A$6,IF($D40=配置调整!$A$8,VLOOKUP($K40,配置调整!$B$4:$O$29,6,0)*配置调整!$A$9,IF($D40=配置调整!$A$11,VLOOKUP($K40,配置调整!$B$4:$O$29,6,0)*配置调整!$A$12,FALSE))) -> 90343545 | N40: ==M40 -> 90343545 | O40: 0 | P40: ==M40 -> 90343545 | Q40: ==M40 -> 90343545 | R40: ==M40 -> 90343545 | S40: 0 | U40: ==IF(OR(L40="标准固收类",L40="非标固收类"),$A$2,"") | V40: ==IF(OR(L40="标准固收类",L40="非标固收类"),EOMONTH($A$2,12),"") | W40: ==IF(OR(L40="标准固收类",L40="非标固收类"),EOMONTH($A$2,A40*12),"") | Y40: ==VLOOKUP(资产明细!K40,配置调整!$B$4:$C$29,2,0) -> 0.07 | Z40: Govt | AC40: H Shares | AD40: ==P40 -> 90343545 | AM40: ==IF(OR(L40="标准固收类",L40="非标固收类"),Y40,"") | BF40: ==AM40 | BG40: ==IF(OR(L40="标准固收类",L40="非标固收类"),"",MIN(Y40,2%)) -> 0.02 | BH40: 0 | BI40: 0.85
B41: MSCI发达市场2 | C41: MSCI发达市场 | D41: 万能账户 | E41: 权益类 | F41: 上市普通股票 | G41: MSCI发达市场 | I41: Generic_MSCI发达市场 | J41: AFS | K41: MSCI发达市场 | L41: 权益类 | M41: ==IF($D41=配置调整!$A$5,VLOOKUP($K41,配置调整!$B$4:$O$29,6,0)*配置调整!$A$6,IF($D41=配置调整!$A$8,VLOOKUP($K41,配置调整!$B$4:$O$29,6,0)*配置调整!$A$9,IF($D41=配置调整!$A$11,VLOOKUP($K41,配置调整!$B$4:$O$29,6,0)*配置调整!$A$12,FALSE))) -> 1.2721636e+08 | N41: ==M41 -> 1.2721636e+08 | O41: 0 | P41: ==M41 -> 1.2721636e+08 | Q41: ==M41 -> 1.2721636e+08 | R41: ==M41 -> 1.2721636e+08 | S41: 0 | U41: ==IF(OR(L41="标准固收类",L41="非标固收类"),$A$2,"") | V41: ==IF(OR(L41="标准固收类",L41="非标固收类"),EOMONTH($A$2,12),"") | W41: ==IF(OR(L41="标准固收类",L41="非标固收类"),EOMONTH($A$2,A41*12),"") | Y41: ==VLOOKUP(资产明细!K41,配置调整!$B$4:$C$29,2,0) -> 0.08 | Z41: Govt | AC41: MSCI DM Shares | AD41: ==P41 -> 1.2721636e+08 | AM41: ==IF(OR(L41="标准固收类",L41="非标固收类"),Y41,"") | BF41: ==AM41 | BG41: ==IF(OR(L41="标准固收类",L41="非标固收类"),"",MIN(Y41,2%)) -> 0.02 | BH41: 0 | BI41: 0.85
...

Sheet 配置调整
D1: check | E1: check | F1: check | G1: 0 | H1: 1 | I1: 2 | J1: 3 | K1: 0 | L1: 1 | M1: 2 | N1: 3 | O1: 0 | P1: 1 | Q1: 2 | R1: 3 | S1: ==SUMPRODUCT(C4:C29,D4:D29) -> 0.030209238 | T1: ==SUMPRODUCT(T4:T13,D4:D13) -> 8.0976457
A2: 资产合计 | C2: 1231 | D2: 传统账户 | E2: 分红账户 | F2: 万能账户 | G2: 传统账户 | H2: 传统账户 | I2: 传统账户 | J2: 传统账户 | K2: 分红账户 | L2: 分红账户 | M2: 分红账户 | N2: 分红账户 | O2: 万能账户 | P2: 万能账户 | Q2: 万能账户 | R2: 万能账户 | S2: ==SUMPRODUCT(S4:S29,D4:D29) -> 0.050371134
A3: ==71125456854.9999*K37 -> 8.0255529e+10 | B3: 资产组合名称/PortfolioName | C3: 预期投资收益率/ExpectedReturn | D3: 配置比例 | E3: 配置比例 | F3: 配置比例 | G3: 配置比例 | H3: 配置比例 | I3: 配置比例 | J3: 配置比例 | K3: 配置比例 | L3: 配置比例 | M3: 配置比例 | N3: 配置比例 | O3: 配置比例 | P3: 配置比例 | Q3: 配置比例 | R3: 配置比例 | S3: 波动率 | V3: 预期投资收益率 | W3: 波动率 | X3: 波动率 | AB3: 节点/Tenor | AC3: Govt
A4: ==SUM(资产明细!M3:M80) -> 8.0255529e+10 | B4: 国债_3Y | C4: 0.011872 | D4: ==SUMIFS(资产明细!$M$3:$M$80,资产明细!$D$3:$D$80,配置调整!D$2,资产明细!$K$3:$K$80,配置调整!$B4)/SUMIFS(资产明细!$M$3:$M$80,资产明细!$D$3:$D$80,配置调整!D$2) -> 0.0036988283 | E4: ==SUMIFS(资产明细!$M$3:$M$80,资产明细!$D$3:$D$80,配置调整!E$2,资产明细!$K$3:$K$80,配置调整!$B4)/SUMIFS(资产明细!$M$3:$M$80,资产明细!$D$3:$D$80,配置调整!E$2) -> 0.0036988283 | F4: ==SUMIFS(资产明细!$M$3:$M$80,资产明细!$D$3:$D$80,配置调整!F$2,资产明细!$K$3:$K$80,配置调整!$B4)/SUMIFS(资产明细!$M$3:$M$80,资产明细!$D$3:$D$80,配置调整!F$2) -> 0.0036988283 | G4: ==Sheet1!L3 -> 0.0036988283 | H4: ==Sheet1!M3 -> 0.018250843 | I4: ==Sheet1!N3 -> 0.024032533 | J4: ==Sheet1!O3 -> 0.0049270319 | K4: ==G4 -> 0.0036988283 | L4: ==H4 -> 0.018250843 | M4: ==I4 -> 0.024032533 | N4: ==J4 -> 0.0049270319 | O4: ==K4 -> 0.0036988283 | P4: ==L4 -> 0.018250843 | Q4: ==M4 -> 0.024032533 | R4: ==N4 -> 0.0049270319 | S4: 0.015 | T4: 2.5 | V4: 2024Q3 | W4: 2024Q3 | X4: 2024Q2 | Z4: 中债曲线 | AB4: 1M | AC4: 0.006635
A5: 传统账户 | B5: 国债_5Y | C5: 0.014152 | D5: ==SUMIFS(资产明细!$M$3:$M$80,资产明细!$D$3:$D$80,配置调整!D$2,资产明细!$K$3:$K$80,配置调整!$B5)/SUMIFS(资产明细!$M$3:$M$80,资产明细!$D$3:$D$80,配置调整!D$2) -> 0.0077904803 | E5: ==SUMIFS(资产明细!$M$3:$M$80,资产明细!$D$3:$D$80,配置调整!E$2,资产明细!$K$3:$K$80,配置调整!$B5)/SUMIFS(资产明细!$M$3:$M$80,资产明细!$D$3:$D$80,配置调整!E$2) -> 0.0077904803 | F5: ==SUMIFS(资产明细!$M$3:$M$80,资产明细!$D$3:$D$80,配置调整!F$2,资产明细!$K$3:$K$80,配置调整!$B5)/SUMIFS(资产明细!$M$3:$M$80,资产明细!$D$3:$D$80,配置调整!F$2) -> 0.0077904803 | G5: ==Sheet1!L4 -> 0.0077904803 | H5: ==Sheet1!M4 -> 0.034165384 | I5: ==Sheet1!N4 -> 0.0025115748 | J5: ==Sheet1!O4 -> 0.0020925844 | K5: ==G5 -> 0.0077904803 | L5: ==H5 -> 0.034165384 | M5: ==I5 -> 0.0025115748 | N5: ==J5 -> 0.0020925844 | O5: ==K5 -> 0.0077904803 | P5: ==L5 -> 0.034165384 | Q5: ==M5 -> 0.0025115748 | R5: ==N5 -> 0.0020925844 | S5: 0.02 | T5: 4 | U5: 国债_10Y | V5: 0.02186 | W5: 0.046489957 | X5: 0.046682 | Y5: ==W5-X5 -> -0.00019204296 | Z5: 0.021518 | AA5: 0.016752 | AB5: 2M | AC5: 0.008532
A6: ==A3/3 -> 2.6751843e+10 | B6: 国债_10Y | C6: 0.016752 | D6: ==SUMIFS(资产明细!$M$3:$M$80,资产明细!$D$3:$D$80,配置调整!D$2,资产明细!$K$3:$K$80,配置调整!$B6)/SUMIFS(资产明细!$M$3:$M$80,资产明细!$D$3:$D$80,配置调整!D$2) -> 0.032496654 | E6: ==SUMIFS(资产明细!$M$3:$M$80,资产明细!$D$3:$D$80,配置调整!E$2,资产明细!$K$3:$K$80,配置调整!$B6)/SUMIFS(资产明细!$M$3:$M$80,资产明细!$D$3:$D$80,配置调整!E$2) -> 0.032496654 | F6: ==SUMIFS(资产明细!$M$3:$M$80,资产明细!$D$3:$D$80,配置调整!F$2,资产明细!$K$3:$K$80,配置调整!$B6)/SUMIFS(资产明细!$M$3:$M$80,资产明细!$D$3:$D$80,配置调整!F$2) -> 0.032496654 | G6: ==Sheet1!L5 -> 0.032496654 | H6: ==Sheet1!M5 -> 7.032092e-05 | I6: ==Sheet1!N5 -> 0.030616004 | J6: ==Sheet1!O5 -> 0.013735449 | K6: ==G6 -> 0.032496654 | L6: ==H6 -> 7.032092e-05 | M6: ==I6 -> 0.030616004 | N6: ==J6 -> 0.013735449 | O6: ==K6 -> 0.032496654 | P6: ==L6 -> 7.032092e-05 | Q6: ==M6 -> 0.030616004 | R6: ==N6 -> 0.013735449 | S6: 0.04 | T6: 8 | U6: 国债_30Y | V6: 0.023965 | W6: 0.10465235 | X6: 0.103864 | Y6: ==W6-X6 -> 0.00078835284 | Z6: 0.02355 | AB6: 3M | AC6: 0.00907
B7: 国债_20Y | C7: 0.019747 | D7: ==SUMIFS(资产明细!$M$3:$M$80,资产明细!$D$3:$D$80,配置调整!D$2,资产明细!$K$3:$K$80,配置调整!$B7)/SUMIFS(资产明细!$M$3:$M$80,资产明细!$D$3:$D$80,配置调整!D$2) -> 0.14212089 | E7: ==SUMIFS(资产明细!$M$3:$M$80,资产明细!$D$3:$D$80,配置调整!E$2,资产明细!$K$3:$K$80,配置调整!$B7)/SUMIFS(资产明细!$M$3:$M$80,资产明细!$D$3:$D$80,配置调整!E$2) -> 0.14212089 | F7: ==SUMIFS(资产明细!$M$3:$M$80,资产明细!$D$3:$D$80,配置调整!F$2,资产明细!$K$3:$K$80,配置调整!$B7)/SUMIFS(资产明细!$M$3:$M$80,资产明细!$D$3:$D$80,配置调整!F$2) -> 0.14212089 | G7: ==Sheet1!L6 -> 0.14212089 | H7: ==Sheet1!M6 -> 0.15746475 | I7: ==Sheet1!N6 -> 0.29297907 | J7: ==Sheet1!O6 -> 0.22835041 | K7: ==G7 -> 0.14212089 | L7: ==H7 -> 0.15746475 | M7: ==I7 -> 0.29297907 | N7: ==J7 -> 0.22835041 | O7: ==K7 -> 0.14212089 | P7: ==L7 -> 0.15746475 | Q7: ==M7 -> 0.29297907 | R7: ==N7 -> 0.22835041 | S7: 0.045 | T7: 14 | U7: 高等级信用债_3Y | V7: 0.023594836 | W7: 0.024324772 | X7: 0.023601 | Y7: ==W7-X7 -> 0.00072377152 | Z7: 0.023248 | AB7: 6M | AC7: 0.009543
A8: 分红账户 | B8: 国债_50Y | C8: 0.019875 | D8: ==SUMIFS(资产明细!$M$3:$M$80,资产明细!$D$3:$D$80,配置调整!D$2,资产明细!$K$3:$K$80,配置调整!$B8)/SUMIFS(资产明细!$M$3:$M$80,资产明细!$D$3:$D$80,配置调整!D$2) -> 0.20614768 | E8: ==SUMIFS(资产明细!$M$3:$M$80,资产明细!$D$3:$D$80,配置调整!E$2,资产明细!$K$3:$K$80,配置调整!$B8)/SUMIFS(资产明细!$M$3:$M$80,资产明细!$D$3:$D$80,配置调整!E$2) -> 0.20614768 | F8: ==SUMIFS(资产明细!$M$3:$M$80,资产明细!$D$3:$D$80,配置调整!F$2,资产明细!$K$3:$K$80,配置调整!$B8)/SUMIFS(资产明细!$M$3:$M$80,资产明细!$D$3:$D$80,配置调整!F$2) -> 0.20614768 | G8: ==Sheet1!L7 -> 0.20614768 | H8: ==Sheet1!M7 -> 0.20431444 | I8: ==Sheet1!N7 -> 0.13835296 | J8: ==Sheet1!O7 -> 0.17315448 | K8: ==G8 -> 0.20614768 | L8: ==H8 -> 0.20431444 | M8: ==I8 -> 0.13835296 | N8: ==J8 -> 0.17315448 | O8: ==K8 -> 0.20614768 | P8: ==L8 -> 0.20431444 | Q8: ==M8 -> 0.13835296 | R8: ==N8 -> 0.17315448 | S8: 0.055 | T8: 25 | U8: 高等级信用债_5Y | V8: 0.023487288 | W8: 0.033847491 | X8: 0.033473 | Y8: ==W8-X8 -> 0.0003744911 | Z8: 0.024018 | AB8: 9M | AC8: 0.010197
A9: ==A3/3 -> 2.6751843e+10 | B9: 信用债_3Y | C9: 0.017501 | D9: ==SUMIFS(资产明细!$M$3:$M$80,资产明细!$D$3:$D$80,配置调整!D$2,资产明细!$K$3:$K$80,配置调整!$B9)/SUMIFS(资产明细!$M$3:$M$80,资产明细!$D$3:$D$80,配置调整!D$2) -> 0.067977585 | E9: ==SUMIFS(资产明细!$M$3:$M$80,资产明细!$D$3:$D$80,配置调整!E$2,资产明细!$K$3:$K$80,配置调整!$B9)/SUMIFS(资产明细!$M$3:$M$80,资产明细!$D$3:$D$80,配置调整!E$2) -> 0.067977585 | F9: ==SUMIFS(资产明细!$M$3:$M$80,资产明细!$D$3:$D$80,配置调整!F$2,资产明细!$K$3:$K$80,配置调整!$B9)/SUMIFS(资产明细!$M$3:$M$80,资产明细!$D$3:$D$80,配置调整!F$2) -> 0.067977585 | G9: ==Sheet1!L8 -> 0.067977585 | H9: ==Sheet1!M8 -> 0.065288002 | I9: ==Sheet1!N8 -> 0.0092608415 | J9: ==Sheet1!O8 -> 0.0047362284 | K9: ==G9 -> 0.067977585 | L9: ==H9 -> 0.065288002 | M9: ==I9 -> 0.0092608415 | N9: ==J9 -> 0.0047362284 | O9: ==K9 -> 0.067977585 | P9: ==L9 -> 0.065288002 | Q9: ==M9 -> 0.0092608415 | R9: ==N9 -> 0.0047362284 | S9: ==W7*C9/V7 -> 0.018042415 | T9: 2.5 | U9: 非标资产_3Y | V9: 0.032748196 | W9: 0.029189726 | X9: 0.0283212 | Y9: ==W9-X9 -> 0.00086852582 | AB9: 12M | AC9: 0.010814
B10: 信用债_5Y | C10: 0.018727 | D10: ==SUMIFS(资产明细!$M$3:$M$80,资产明细!$D$3:$D$80,配置调整!D$2,资产明细!$K$3:$K$80,配置调整!$B10)/SUMIFS(资产明细!$M$3:$M$80,资产明细!$D$3:$D$80,配置调整!D$2) -> 0.0059782634 | E10: ==SUMIFS(资产明细!$M$3:$M$80,资产明细!$D$3:$D$80,配置调整!E$2,资产明细!$K$3:$K$80,配置调整!$B10)/SUMIFS(资产明细!$M$3:$M$80,资产明细!$D$3:$D$80,配置调整!E$2) -> 0.0059782634 | F10: ==SUMIFS(资产明细!$M$3:$M$80,资产明细!$D$3:$D$80,配置调整!F$2,资产明细!$K$3:$K$80,配置调整!$B10)/SUMIFS(资产明细!$M$3:$M$80,资产明细!$D$3:$D$80,配置调整!F$2) -> 0.0059782634 | G10: ==Sheet1!L9 -> 0.0059782634 | H10: ==Sheet1!M9 -> 4.1665381e-12 | I10: ==Sheet1!N9 -> 0.017289853 | J10: ==Sheet1!O9 -> 0.00087263177 | K10: ==G10 -> 0.0059782634 | L10: ==H10 -> 4.1665381e-12 | M10: ==I10 -> 0.017289853 | N10: ==J10 -> 0.00087263177 | O10: ==K10 -> 0.0059782634 | P10: ==L10 -> 4.1665381e-12 | Q10: ==M10 -> 0.017289853 | R10: ==N10 -> 0.00087263177 | S10: ==W8*C10/V8 -> 0.026987448 | T10: 4 | U10: 非标资产_5Y | V10: 0.032143778 | W10: 0.040616989 | X10: 0.0401676 | Y10: ==W10-X10 -> 0.00044938932 | AB10: 24M | AC10: 0.011375
A11: 万能账户 | B11: 信用债_10Y | C11: 0.021173 | D11: ==SUMIFS(资产明细!$M$3:$M$80,资产明细!$D$3:$D$80,配置调整!D$2,资产明细!$K$3:$K$80,配置调整!$B11)/SUMIFS(资产明细!$M$3:$M$80,资产明细!$D$3:$D$80,配置调整!D$2) -> 0.039135613 | E11: ==SUMIFS(资产明细!$M$3:$M$80,资产明细!$D$3:$D$80,配置调整!E$2,资产明细!$K$3:$K$80,配置调整!$B11)/SUMIFS(资产明细!$M$3:$M$80,资产明细!$D$3:$D$80,配置调整!E$2) -> 0.039135613 | F11: ==SUMIFS(资产明细!$M$3:$M$80,资产明细!$D$3:$D$80,配置调整!F$2,资产明细!$K$3:$K$80,配置调整!$B11)/SUMIFS(资产明细!$M$3:$M$80,资产明细!$D$3:$D$80,配置调整!F$2) -> 0.039135613 | G11: ==Sheet1!L10 -> 0.039135613 | H11: ==Sheet1!M10 -> 0.065497096 | I11: ==Sheet1!N10 -> 0.015324656 | J11: ==Sheet1!O10 -> 0.027221905 | K11: ==G11 -> 0.039135613 | L11: ==H11 -> 0.065497096 | M11: ==I11 -> 0.015324656 | N11: ==J11 -> 0.027221905 | O11: ==K11 -> 0.039135613 | P11: ==L11 -> 0.065497096 | Q11: ==M11 -> 0.015324656 | R11: ==N11 -> 0.027221905 | S11: ==[19]自定义指标!$B$10/[19]自定义指标!$B$9*S10 -> 0.043288127 | T11: 8 | U11: A股 | V11: 0.091774815 | W11: 0.25066148 | X11: 0.24764 | Y11: ==W11-X11 -> 0.0030214811 | AB11: 36M | AC11: 0.011881
A12: ==A3/3 -> 2.6751843e+10 | B12: 非标资产_3Y | C12: 0.024290322 | D12: ==SUMIFS(资产明细!$M$3:$M$80,资产明细!$D$3:$D$80,配置调整!D$2,资产明细!$K$3:$K$80,配置调整!$B12)/SUMIFS(资产明细!$M$3:$M$80,资产明细!$D$3:$D$80,配置调整!D$2) -> 0.028692128 | E12: ==SUMIFS(资产明细!$M$3:$M$80,资产明细!$D$3:$D$80,配置调整!E$2,资产明细!$K$3:$K$80,配置调整!$B12)/SUMIFS(资产明细!$M$3:$M$80,资产明细!$D$3:$D$80,配置调整!E$2) -> 0.028692128 | F12: ==SUMIFS(资产明细!$M$3:$M$80,资产明细!$D$3:$D$80,配置调整!F$2,资产明细!$K$3:$K$80,配置调整!$B12)/SUMIFS(资产明细!$M$3:$M$80,资产明细!$D$3:$D$80,配置调整!F$2) -> 0.028692128 | G12: ==Sheet1!L11 -> 0.028692128 | H12: ==Sheet1!M11 -> 0.00021312637 | I12: ==Sheet1!N11 -> 0.0074794708 | J12: ==Sheet1!O11 -> 0.0071535672 | K12: ==G12 -> 0.028692128 | L12: ==H12 -> 0.00021312637 | M12: ==I12 -> 0.0074794708 | N12: ==J12 -> 0.0071535672 | O12: ==K12 -> 0.028692128 | P12: ==L12 -> 0.00021312637 | Q12: ==M12 -> 0.0074794708 | R12: ==N12 -> 0.0071535672 | S12: ==W9*C12/V9 -> 0.021650898 | T12: 2.5 | U12: H股 | V12: 0.1021779 | W12: 0.21063241 | X12: 0.210144 | Y12: ==W12-X12 -> 0.00048840931 | AB12: 48M | AC12: 0.012961
B13: 非标资产_5Y | C13: 0.025629035 | D13: ==SUMIFS(资产明细!$M$3:$M$80,资产明细!$D$3:$D$80,配置调整!D$2,资产明细!$K$3:$K$80,配置调整!$B13)/SUMIFS(资产明细!$M$3:$M$80,资产明细!$D$3:$D$80,配置调整!D$2) -> 0.018801727 | E13: ==SUMIFS(资产明细!$M$3:$M$80,资产明细!$D$3:$D$80,配置调整!E$2,资产明细!$K$3:$K$80,配置调整!$B13)/SUMIFS(资产明细!$M$3:$M$80,资产明细!$D$3:$D$80,配置调整!E$2) -> 0.018801727 | F13: ==SUMIFS(资产明细!$M$3:$M$80,资产明细!$D$3:$D$80,配置调整!F$2,资产明细!$K$3:$K$80,配置调整!$B13)/SUMIFS(资产明细!$M$3:$M$80,资产明细!$D$3:$D$80,配置调整!F$2) -> 0.018801727 | G13: ==Sheet1!L12 -> 0.018801727 | H13: ==Sheet1!M12 -> 0.018435449 | I13: ==Sheet1!N12 -> 0.011006803 | J13: ==Sheet1!O12 -> 0.026071855 | K13: ==G13 -> 0.018801727 | L13: ==H13 -> 0.018435449 | M13: ==I13 -> 0.011006803 | N13: ==J13 -> 0.026071855 | O13: ==K13 -> 0.018801727 | P13: ==L13 -> 0.018435449 | Q13: ==M13 -> 0.011006803 | R13: ==N13 -> 0.026071855 | S13: ==W10*C13/V10 -> 0.032384938 | T13: 4 | U13: MSCI发达市场 | V13: 0.06965 | W13: 0.1673502 | X13: 0.16775 | Y13: ==W13-X13 -> -0.00039979604 | AB13: 60M | AC13: 0.014212
B14: A股 | C14: 0.06 | D14: ==SUMIFS(资产明细!$M$3:$M$80,资产明细!$D$3:$D$80,配置调整!D$2,资产明细!$K$3:$K$80,配置调整!$B14)/SUMIFS(资产明细!$M$3:$M$80,资产明细!$D$3:$D$80,配置调整!D$2) -> 1e-05 | E14: ==SUMIFS(资产明细!$M$3:$M$80,资产明细!$D$3:$D$80,配置调整!E$2,资产明细!$K$3:$K$80,配置调整!$B14)/SUMIFS(资产明细!$M$3:$M$80,资产明细!$D$3:$D$80,配置调整!E$2) -> 1e-05 | F14: ==SUMIFS(资产明细!$M$3:$M$80,资产明细!$D$3:$D$80,配置调整!F$2,资产明细!$K$3:$K$80,配置调整!$B14)/SUMIFS(资产明细!$M$3:$M$80,资产明细!$D$3:$D$80,配置调整!F$2) -> 1e-05 | G14: ==Sheet1!L13 -> 1e-05 | H14: ==Sheet1!M13 -> 0.0030906251 | I14: ==Sheet1!N13 -> 0.023195612 | J14: ==Sheet1!O13 -> 0.00013797208 | K14: ==G14 -> 1e-05 | L14: ==H14 -> 0.0030906251 | M14: ==I14 -> 0.023195612 | N14: ==J14 -> 0.00013797208 | O14: ==K14 -> 1e-05 | P14: ==L14 -> 0.0030906251 | Q14: ==M14 -> 0.023195612 | R14: ==N14 -> 0.00013797208 | S14: 0.165 | U14: MSCI新兴市场 | V14: 0.077 | W14: 0.22586533 | X14: 0.226314 | Y14: ==W14-X14 -> -0.000448669 | AB14: 72M | AC14: 0.015145
B15: H股 | C15: 0.07 | D15: ==SUMIFS(资产明细!$M$3:$M$80,资产明细!$D$3:$D$80,配置调整!D$2,资产明细!$K$3:$K$80,配置调整!$B15)/SUMIFS(资产明细!$M$3:$M$80,资产明细!$D$3:$D$80,配置调整!D$2) -> 0.0033770961 | E15: ==SUMIFS(资产明细!$M$3:$M$80,资产明细!$D$3:$D$80,配置调整!E$2,资产明细!$K$3:$K$80,配置调整!$B15)/SUMIFS(资产明细!$M$3:$M$80,资产明细!$D$3:$D$80,配置调整!E$2) -> 0.0033770961 | F15: ==SUMIFS(资产明细!$M$3:$M$80,资产明细!$D$3:$D$80,配置调整!F$2,资产明细!$K$3:$K$80,配置调整!$B15)/SUMIFS(资产明细!$M$3:$M$80,资产明细!$D$3:$D$80,配置调整!F$2) -> 0.0033770961 | G15: ==Sheet1!L14 -> 0.0033770961 | H15: ==Sheet1!M14 -> 4.9218324e-09 | I15: ==Sheet1!N14 -> 0.019530684 | J15: ==Sheet1!O14 -> 0.0086970601 | K15: ==G15 -> 0.0033770961 | L15: ==H15 -> 4.9218324e-09 | M15: ==I15 -> 0.019530684 | N15: ==J15 -> 0.0086970601 | O15: ==K15 -> 0.0033770961 | P15: ==L15 -> 4.9218324e-09 | Q15: ==M15 -> 0.019530684 | R15: ==N15 -> 0.0086970601 | S15: 0.18 | U15: 纯债基金 | V15: 0.028487288 | W15: 0.035443014 | X15: 0.035796 | Y15: ==W15-X15 -> -0.00035298607 | AB15: 84M | AC15: 0.01601
B16: MSCI发达市场 | C16: 0.08 | D16: ==SUMIFS(资产明细!$M$3:$M$80,资产明细!$D$3:$D$80,配置调整!D$2,资产明细!$K$3:$K$80,配置调整!$B16)/SUMIFS(资产明细!$M$3:$M$80,资产明细!$D$3:$D$80,配置调整!D$2) -> 0.0047554241 | E16: ==SUMIFS(资产明细!$M$3:$M$80,资产明细!$D$3:$D$80,配置调整!E$2,资产明细!$K$3:$K$80,配置调整!$B16)/SUMIFS(资产明细!$M$3:$M$80,资产明细!$D$3:$D$80,配置调整!E$2) -> 0.0047554241 | F16: ==SUMIFS(资产明细!$M$3:$M$80,资产明细!$D$3:$D$80,配置调整!F$2,资产明细!$K$3:$K$80,配置调整!$B16)/SUMIFS(资产明细!$M$3:$M$80,资产明细!$D$3:$D$80,配置调整!F$2) -> 0.0047554241 | G16: ==Sheet1!L15 -> 0.0047554241 | H16: ==Sheet1!M15 -> 0.027372612 | I16: ==Sheet1!N15 -> 0.017012064 | J16: ==Sheet1!O15 -> 0.056394661 | K16: ==G16 -> 0.0047554241 | L16: ==H16 -> 0.027372612 | M16: ==I16 -> 0.017012064 | N16: ==J16 -> 0.056394661 | O16: ==K16 -> 0.0047554241 | P16: ==L16 -> 0.027372612 | Q16: ==M16 -> 0.017012064 | R16: ==N16 -> 0.056394661 | S16: ==W13*0.9 -> 0.15061518 | U16: 混合基金 | V16: 0.066459804 | W16: 0.17649996 | X16: 0.173712 | Y16: ==W16-X16 -> 0.0027879585 | AB16: 96M | AC16: 0.01659
B17: MSCI新兴市场 | C17: 0.085 | D17: ==SUMIFS(资产明细!$M$3:$M$80,资产明细!$D$3:$D$80,配置调整!D$2,资产明细!$K$3:$K$80,配置调整!$B17)/SUMIFS(资产明细!$M$3:$M$80,资产明细!$D$3:$D$80,配置调整!D$2) -> 0.025377513 | E17: ==SUMIFS(资产明细!$M$3:$M$80,资产明细!$D$3:$D$80,配置调整!E$2,资产明细!$K$3:$K$80,配置调整!$B17)/SUMIFS(资产明细!$M$3:$M$80,资产明细!$D$3:$D$80,配置调整!E$2) -> 0.025377513 | F17: ==SUMIFS(资产明细!$M$3:$M$80,资产明细!$D$3:$D$80,配置调整!F$2,资产明细!$K$3:$K$80,配置调整!$B17)/SUMIFS(资产明细!$M$3:$M$80,资产明细!$D$3:$D$80,配置调整!F$2) -> 0.025377513 | G17: ==Sheet1!L16 -> 0.025377513 | H17: ==Sheet1!M16 -> 0.056412323 | I17: ==Sheet1!N16 -> 0.037003146 | J17: ==Sheet1!O16 -> 0.028298835 | K17: ==G17 -> 0.025377513 | L17: ==H17 -> 0.056412323 | M17: ==I17 -> 0.037003146 | N17: ==J17 -> 0.028298835 | O17: ==K17 -> 0.025377513 | P17: ==L17 -> 0.056412323 | Q17: ==M17 -> 0.037003146 | R17: ==N17 -> 0.028298835 | S17: ==W14*0.9 -> 0.2032788 | U17: 股票基金 | V17: 0.085446062 | W17: 0.22425377 | X17: 0.220681 | Y17: ==W17-X17 -> 0.0035727656 | AB17: 108M | AC17: 0.016766
B18: 债券基金 | C18: 0.028487288 | D18: ==SUMIFS(资产明细!$M$3:$M$80,资产明细!$D$3:$D$80,配置调整!D$2,资产明细!$K$3:$K$80,配置调整!$B18)/SUMIFS(资产明细!$M$3:$M$80,资产明细!$D$3:$D$80,配置调整!D$2) -> 1e-05 | E18: ==SUMIFS(资产明细!$M$3:$M$80,资产明细!$D$3:$D$80,配置调整!E$2,资产明细!$K$3:$K$80,配置调整!$B18)/SUMIFS(资产明细!$M$3:$M$80,资产明细!$D$3:$D$80,配置调整!E$2) -> 1e-05 | F18: ==SUMIFS(资产明细!$M$3:$M$80,资产明细!$D$3:$D$80,配置调整!F$2,资产明细!$K$3:$K$80,配置调整!$B18)/SUMIFS(资产明细!$M$3:$M$80,资产明细!$D$3:$D$80,配置调整!F$2) -> 1e-05 | G18: ==Sheet1!L17 -> 1e-05 | H18: ==Sheet1!M17 -> 0.00039173317 | I18: ==Sheet1!N17 -> 1.7707171e-07 | J18: ==Sheet1!O17 -> 0.00029124044 | K18: ==G18 -> 1e-05 | L18: ==H18 -> 0.00039173317 | M18: ==I18 -> 1.7707171e-07 | N18: ==J18 -> 0.00029124044 | O18: ==K18 -> 1e-05 | P18: ==L18 -> 0.00039173317 | Q18: ==M18 -> 1.7707171e-07 | R18: ==N18 -> 0.00029124044 | S18: ==W15 -> 0.035443014 | U18: 优先股 | V18: 0.055 | W18: 0.16924168 | X18: 0.170314 | Y18: ==W18-X18 -> -0.0010723229 | AB18: 120M | AC18: 0.016972
B19: 货币基金 | C19: 0.015 | D19: ==SUMIFS(资产明细!$M$3:$M$80,资产明细!$D$3:$D$80,配置调整!D$2,资产明细!$K$3:$K$80,配置调整!$B19)/SUMIFS(资产明细!$M$3:$M$80,资产明细!$D$3:$D$80,配置调整!D$2) -> 1e-05 | E19: ==SUMIFS(资产明细!$M$3:$M$80,资产明细!$D$3:$D$80,配置调整!E$2,资产明细!$K$3:$K$80,配置调整!$B19)/SUMIFS(资产明细!$M$3:$M$80,资产明细!$D$3:$D$80,配置调整!E$2) -> 1e-05 | F19: ==SUMIFS(资产明细!$M$3:$M$80,资产明细!$D$3:$D$80,配置调整!F$2,资产明细!$K$3:$K$80,配置调整!$B19)/SUMIFS(资产明细!$M$3:$M$80,资产明细!$D$3:$D$80,配置调整!F$2) -> 1e-05 | G19: ==Sheet1!L18 -> 1e-05 | H19: ==Sheet1!M18 -> 1.0556649e-138 | I19: ==Sheet1!N18 -> 0 | J19: ==Sheet1!O18 -> 0 | K19: ==G19 -> 1e-05 | L19: ==H19 -> 1.0556649e-138 | M19: ==I19 -> 0 | N19: ==J19 -> 0 | O19: ==K19 -> 1e-05 | P19: ==L19 -> 1.0556649e-138 | Q19: ==M19 -> 0 | R19: ==N19 -> 0 | S19: 0.005 | U19: 可转债 | V19: 0.05 | W19: 0.15555801 | X19: 0.155761 | Y19: ==W19-X19 -> -0.00020298881 | AB19: 180M | AC19: 0.019189
B20: 混合基金 | C20: 0.05 | D20: ==SUMIFS(资产明细!$M$3:$M$80,资产明细!$D$3:$D$80,配置调整!D$2,资产明细!$K$3:$K$80,配置调整!$B20)/SUMIFS(资产明细!$M$3:$M$80,资产明细!$D$3:$D$80,配置调整!D$2) -> 0.010751247 | E20: ==SUMIFS(资产明细!$M$3:$M$80,资产明细!$D$3:$D$80,配置调整!E$2,资产明细!$K$3:$K$80,配置调整!$B20)/SUMIFS(资产明细!$M$3:$M$80,资产明细!$D$3:$D$80,配置调整!E$2) -> 0.010751247 | F20: ==SUMIFS(资产明细!$M$3:$M$80,资产明细!$D$3:$D$80,配置调整!F$2,资产明细!$K$3:$K$80,配置调整!$B20)/SUMIFS(资产明细!$M$3:$M$80,资产明细!$D$3:$D$80,配置调整!F$2) -> 0.010751247 | G20: ==Sheet1!L19 -> 0.010751247 | H20: ==Sheet1!M19 -> 0 | I20: ==Sheet1!N19 -> 2.1006208e-59 | J20: ==Sheet1!O19 -> 0 | K20: ==G20 -> 0.010751247 | L20: ==H20 -> 0 | M20: ==I20 -> 2.1006208e-59 | N20: ==J20 -> 0 | O20: ==K20 -> 0.010751247 | P20: ==L20 -> 0 | Q20: ==M20 -> 2.1006208e-59 | R20: ==N20 -> 0 | S20: ==W16*0.9 -> 0.15884996 | U20: 长期股权投资 | V20: 0.1044455 | W20: 0.19302347 | X20: 0.194181 | Y20: ==W20-X20 -> -0.0011575277 | AB20: 240M | AC20: 0.020266
